Workbook

Sheet ORDERS
A1: Order ID | B1: Date | C1: Sales | D1: New Party | E1: Route | F1: Party Code | G1: Party Name | H1: Area | I1: Remarks | J1: Tank | K1: Size | L1: Qty | M1: Col | N1: Lay | O1: Rate | P1: Tank | Q1: Size | R1: Qty | S1: Col | T1: Lay | U1: Rate | V1: Tank | W1: Size | X1: Qty | Y1: Col | Z1: Lay | AA1: Rate | AB1: Tank | AC1: Size | AD1: Qty | AE1: Col | AF1: Lay | AG1: Rate | AH1: Tank | AI1: Size | AJ1: Qty | AK1: Col | AL1: Lay | AM1: Rate | AN1: Tank | AO1: Size | AP1: Qty | AQ1: Col | AR1: Lay | AS1: Rate | AT1: Tank | AU1: Size | AV1: Qty | AW1: Col | AX1: Lay | AY1: Rate | AZ1: Tank | BA1: Size | BB1: Qty | BC1: Col | BD1: Lay | BE1: Rate | BF1: Tank | BG1: Size | BH1: Qty | BI1: Col | BJ1: Lay | BK1: Rate | BL1: Tank | BM1: Size | BN1: Qty | BO1: Col | BP1: Lay | BQ1: Rate | BR1: Terms | BS1: Site Delivery | BT1: =K1*L1+Q1*R1+W1*X1+AC1*AD1+AI1*AJ1+AO1*AP1+AU1*AV1+BA1*BB1+BG1*BH1+BM1*BN1 -> #VALUE!
A2: 21175 | B2: 46020 | C2: BR | D2: No | E2: Dave | F2: SHIV18 | G2: Dhanlaxmi Hw | H2: Santebennur | J2: AG | K2: 500 | L2: 2 | M2: Y | N2: 3L | O2: 4.2 | P2: AG | Q2: 500 | R2: 2 | S2: W | T2: 3L | U2: 4.2 | V2: AG | W2: 750 | X2: 2 | Y2: W | Z2: 3L | AA2: 4.2 | BR2: 7 days | BT2: =K2*L2+Q2*R2+W2*X2+AC2*AD2+AI2*AJ2+AO2*AP2+AU2*AV2+BA2*BB2+BG2*BH2+BM2*BN2 -> 3500
A3: 21225 | B3: 46023 | C3: RP | D3: No | E3: BALL | F3: N R Ball 01 | G3: Vishnu Agency | H3: Parasuramapura | I3: 0.40 Cod | J3: AG | K3: 500 | L3: 5 | M3: Y | N3: 3L | O3: 3.6 | P3: AG | Q3: 500 | R3: 5 | S3: W | T3: 3L | U3: 3.6 | V3: AG | W3: 750 | X3: 3 | Y3: W | Z3: 3L | AA3: 3.6 | AB3: AG | AC3: 750 | AD3: 3 | AE3: Y | AF3: 3L | AG3: 3.6 | BR3: 7 days | BT3: =K3*L3+Q3*R3+W3*X3+AC3*AD3+AI3*AJ3+AO3*AP3+AU3*AV3+BA3*BB3+BG3*BH3+BM3*BN3 -> 9500
A4: 21223 | B4: 46022 | C4: BR | D4: No | E4: Hass | F4: Nagamangala | G4: Saraswati enterprise | H4: Nagamangala | J4: AG | K4: 1000 | L4: 3 | M4: W | N4: 3L | O4: 3.5 | P4: AG | Q4: 500 | R4: 2 | S4: W | T4: 3L | U4: 3.5 | V4: AG | W4: 1500 | X4: 1 | Y4: W | Z4: 3L | AA4: ,3.50 | AB4: AG | AC4: 2000 | AD4: 1 | AE4: W | AF4: 3L | AG4: 3.5 | AH4: AG | AI4: 1000 | AJ4: 2 | AK4: Y | AL4: 3L | AM4: 3.5 | AN4: AG | AO4: 500 | AP4: 3 | AQ4: Y | AR4: 3L | AS4: 3.5 | BR4: COD | BS4: 3.50 +50 | BT4: =K4*L4+Q4*R4+W4*X4+AC4*AD4+AI4*AJ4+AO4*AP4+AU4*AV4+BA4*BB4+BG4*BH4+BM4*BN4 -> 11000
A5: 21178 | B5: 46021 | C5: BR | D5: No | E5: Hubli | F5: Kumta | G5: Raj granite | H5: Kumta | J5: AG | K5: 1000 | L5: 10 | M5: Y | N5: 3L | O5: 3.8 | P5: AG | Q5: 1000 | R5: 8 | S5: F | T5: 3L | U5: 3.8 | BR5: COD | BT5: =K5*L5+Q5*R5+W5*X5+AC5*AD5+AI5*AJ5+AO5*AP5+AU5*AV5+BA5*BB5+BG5*BH5+BM5*BN5 -> 18000
A6: 21185 | B6: 46021 | C6: BR | D6: No | E6: Hubli | F6: Kustagi | G6: Pawan traders | H6: Kustagi | J6: AG | K6: 750 | L6: 10 | M6: Y | N6: 3L | O6: 3.8 | P6: AG | Q6: 1000 | R6: 10 | S6: Y | T6: 3L | U6: 3.8 | BR6: COD | BT6: =K6*L6+Q6*R6+W6*X6+AC6*AD6+AI6*AJ6+AO6*AP6+AU6*AV6+BA6*BB6+BG6*BH6+BM6*BN6 -> 17500
A7: 21226 | B7: 46023 | C7: RP | D7: No | E7: R1 | F7: N R 199 | G7: Mahalakshmi Ele&Hw | H7: Doddaballapur | J7: AG | K7: 1000 | L7: 2 | M7: W | N7: 3L | O7: 4.3 | P7: AG | Q7: 1000 | R7: 1 | S7: Y | T7: 3L | U7: 4.3 | BR7: 7 days | BT7: =K7*L7+Q7*R7+W7*X7+AC7*AD7+AI7*AJ7+AO7*AP7+AU7*AV7+BA7*BB7+BG7*BH7+BM7*BN7 -> 3000
A8: 21227 | B8: 46023 | C8: RP | D8: No | E8: R1 | F8: R 101 | G8: Balaji Hw&Ele | H8: Doddaballapur | I8: 0.40 Cod | J8: AG | K8: 1500 | L8: 1 | M8: Y | N8: 3L | O8: 3.7 | BR8: 7 days | BS8: 8867438103 | BT8: =K8*L8+Q8*R8+W8*X8+AC8*AD8+AI8*AJ8+AO8*AP8+AU8*AV8+BA8*BB8+BG8*BH8+BM8*BN8 -> 1500
A9: 21228 | B9: 46023 | C9: RP | D9: No | E9: R1 | F9: N R 110 | G9: Raj Lakshmi Hw&Ele | H9: Sadahalli | I9: 0.40 Cod | J9: AG | K9: 1000 | L9: 1 | M9: Y | N9: 3L | O9: 3.7 | P9: AG | Q9: 500 | R9: 1 | S9: Y | T9: 3L | U9: 3.7 | BR9: 7 days | BT9: =K9*L9+Q9*R9+W9*X9+AC9*AD9+AI9*AJ9+AO9*AP9+AU9*AV9+BA9*BB9+BG9*BH9+BM9*BN9 -> 1500
A10: 21232 | B10: 46023 | C10: MG | D10: No | E10: R1 | F10: 218 | G10: Aditya enterprise | H10: Jakkur | J10: AG | K10: 1500 | L10: 1 | M10: Y | N10: 3L | O10: 4.2 | BR10: 7 days | BT10: =K10*L10+Q10*R10+W10*X10+AC10*AD10+AI10*AJ10+AO10*AP10+AU10*AV10+BA10*BB10+BG10*BH10+BM10*BN10 -> 1500
A11: 21233 | B11: 46023 | C11: RP | D11: No | E11: R1 | F11: R 129 | G11: Ramdev Ele&Hw | H11: Bagalur | I11: 0.40 Cod | J11: AG | K11: 1000 | L11: 1 | M11: Y | N11: 3L | O11: 3.7 | BR11: 7 days | BT11: =K11*L11+Q11*R11+W11*X11+AC11*AD11+AI11*AJ11+AO11*AP11+AU11*AV11+BA11*BB11+BG11*BH11+BM11*BN11 -> 1000
A12: 21234 | B12: 46023 | C12: RP | D12: No | E12: R1 | F12: N R 107 | G12: Clty Hw&Ele | H12: Hosahalli | I12: 0.40 Cod | J12: AG | K12: 1000 | L12: 2 | M12: Y | N12: 3L | O12: 3.7 | BR12: 7 days | BT12: =K12*L12+Q12*R12+W12*X12+AC12*AD12+AI12*AJ12+AO12*AP12+AU12*AV12+BA12*BB12+BG12*BH12+BM12*BN12 -> 2000
A13: 21235 | B13: 46024 | C13: BR | D13: No | E13: R1 | F13: 137 | G13: Ganga traders | H13: Boopsandra | J13: AG | K13: 1000 | L13: 1 | M13: Y | N13: 3L | O13: 4.2 | BR13: COD | BT13: =K13*L13+Q13*R13+W13*X13+AC13*AD13+AI13*AJ13+AO13*AP13+AU13*AV13+BA13*BB13+BG13*BH13+BM13*BN13 -> 1000
A14: 21219 | B14: 46022 | C14: RP | D14: No | E14: R1 | F14: N R 112 | G14: Jagdamba Hw/Ele | H14: Thammenahalli | J14: AG | K14: 1000 | L14: 2 | M14: W | N14: 5L | O14: 5.2 | BR14: 7 days | BS14: 9606138634 | BT14: =K14*L14+Q14*R14+W14*X14+AC14*AD14+AI14*AJ14+AO14*AP14+AU14*AV14+BA14*BB14+BG14*BH14+BM14*BN14 -> 2000
A15: 21241 | B15: 46024 | C15: MG | D15: No | E15: R1 | F15: 125 | G15: Sai Shiva traders | H15: Soladevanahalli | I15: 9980931990 | J15: AG | K15: 2000 | L15: 1 | M15: W | N15: 3L | O15: 4.2 | BR15: 7 days | BT15: =K15*L15+Q15*R15+W15*X15+AC15*AD15+AI15*AJ15+AO15*AP15+AU15*AV15+BA15*BB15+BG15*BH15+BM15*BN15 -> 2000
A16: 21221 | B16: 46022 | C16: MG | D16: No | E16: R2 | F16: R263 | G16: Harsha hardware | H16: Doddagubi | J16: AG | K16: 1000 | L16: 1 | M16: Y | N16: 3L | O16: 4.2 | BR16: 7 days | BT16: =K16*L16+Q16*R16+W16*X16+AC16*AD16+AI16*AJ16+AO16*AP16+AU16*AV16+BA16*BB16+BG16*BH16+BM16*BN16 -> 1000
A17: 21229 | B17: 46023 | C17: RP | D17: No | E17: R2 | F17: N M101 | G17: Classic Hw/ | H17: Doddagubbi | I17: 0.40 Cod | J17: AG | K17: 1000 | L17: 2 | M17: W | N17: 3L | O17: 3.7 | BR17: 7 days | BS17: 8220310360 | BT17: =K17*L17+Q17*R17+W17*X17+AC17*AD17+AI17*AJ17+AO17*AP17+AU17*AV17+BA17*BB17+BG17*BH17+BM17*BN17 -> 2000
A18: 21231 | B18: 46023 | C18: MG | D18: No | E18: R2 | F18: 218 | G18: Aditya enterprise | H18: D j Halli | I18: .40 cod | J18: AG | K18: 750 | L18: 4 | M18: Y | N18: 3L | O18: 3.55 | BR18: 7 days | BT18: =K18*L18+Q18*R18+W18*X18+AC18*AD18+AI18*AJ18+AO18*AP18+AU18*AV18+BA18*BB18+BG18*BH18+BM18*BN18 -> 3000
A19: 21237 | B19: 46024 | C19: RP | D19: No | E19: R2 | F19: R 232 | G19: G K Trader | H19: K G Halli | I19: 0.40 Cod | J19: AG | K19: 1000 | L19: 2 | M19: Y | N19: 3L | O19: 3.7 | BR19: 7 days | BT19: =K19*L19+Q19*R19+W19*X19+AC19*AD19+AI19*AJ19+AO19*AP19+AU19*AV19+BA19*BB19+BG19*BH19+BM19*BN19 -> 2000
A20: 21239 | B20: 46024 | C20: MG | D20: No | E20: R2 | F20: 248 | G20: Sai ceramic | H20: T s Halli | I20: .40 cod | J20: AG | K20: 2000 | L20: 1 | M20: Y | N20: 3L | O20: 3.8 | P20: AG | Q20: 1000 | R20: 2 | S20: Y | T20: 3L | U20: 3.8 | V20: AG | W20: 500 | X20: 2 | Y20: Y | Z20: 3L | AA20: 3.8 | BR20: 7 days | BT20: =K20*L20+Q20*R20+W20*X20+AC20*AD20+AI20*AJ20+AO20*AP20+AU20*AV20+BA20*BB20+BG20*BH20+BM20*BN20 -> 5000
A21: 21240 | B21: 46024 | C21: MG | D21: No | E21: R2 | F21: 125 | G21: Sai Shiva traders | H21: Laggere | J21: AG | K21: 1000 | L21: 1 | M21: W | N21: 3L | O21: 4.2 | BR21: 7 days | BS21: 9980931990 | BT21: =K21*L21+Q21*R21+W21*X21+AC21*AD21+AI21*AJ21+AO21*AP21+AU21*AV21+BA21*BB21+BG21*BH21+BM21*BN21 -> 1000
A22: 21236 | B22: 46024 | C22: BR | D22: No | E22: R3 | F22: BR 301 | G22: Mahendra Hw | H22: Bolare kanakpura mn road | J22: AG | K22: 1000 | L22: 2 | M22: Y | N22: 3L | O22: 4.2 | P22: AG | Q22: 500 | R22: 1 | S22: Y | T22: 3L | U22: 4.2 | BR22: COD | BT22: =K22*L22+Q22*R22+W22*X22+AC22*AD22+AI22*AJ22+AO22*AP22+AU22*AV22+BA22*BB22+BG22*BH22+BM22*BN22 -> 2500
A23: 21208 | B23: 46022 | C23: SB | D23: No | E23: R5 | F23: G721 | G23: Ppsh/w& paints | H23: Mysore road.guddadahalli | J23: AG | K23: 1500 | L23: 3 | M23: Y | N23: 3L | O23: 4.2 | BR23: 7 days | BS23: 9980475875.Aslam.guddadahalli.mysore road | BT23: =K23*L23+Q23*R23+W23*X23+AC23*AD23+AI23*AJ23+AO23*AP23+AU23*AV23+BA23*BB23+BG23*BH23+BM23*BN23 -> 4500
A24: 21209 | B24: 46022 | C24: SB | D24: No | E24: R5 | F24: G721 | G24: Pps h/w&paints | H24: Gangondanahalli main road | J24: AG | K24: 1000 | L24: 2 | M24: Y | N24: 3L | O24: 4.2 | BR24: 7 days | BT24: =K24*L24+Q24*R24+W24*X24+AC24*AD24+AI24*AJ24+AO24*AP24+AU24*AV24+BA24*BB24+BG24*BH24+BM24*BN24 -> 2000
A25: 21222 | B25: 46022 | C25: SB | D25: No | E25: R7 | F25: 726 | G25: Lakshmi h/w | H25: Hegganahalli | J25: AG | K25: 1000 | L25: 1 | M25: Y | N25: 3L | O25: 4.2 | BR25: 7 days | BT25: =K25*L25+Q25*R25+W25*X25+AC25*AD25+AI25*AJ25+AO25*AP25+AU25*AV25+BA25*BB25+BG25*BH25+BM25*BN25 -> 1000
A26: 21224 | B26: 46022 | C26: BR | D26: No | E26: R7 | F26: BR 704 | G26: Mahaveer Hw | H26: Gollarahatti | J26: AG | K26: 1000 | L26: 1 | M26: Y | N26: 3L | O26: 4.2 | BR26: COD | BT26: =K26*L26+Q26*R26+W26*X26+AC26*AD26+AI26*AJ26+AO26*AP26+AU26*AV26+BA26*BB26+BG26*BH26+BM26*BN26 -> 1000
A27: 21220 | B27: 46022 | C27: A/C | D27: No | E27: R8 | F27: 803 | G27: EESHWARA ENT | H27: BOMMANAHALLI | J27: AG | K27: 3000 | L27: 1 | M27: Y | N27: 3L | O27: 4.3 | BR27: COD | BS27: SITE DELIVERY | BT27: =K27*L27+Q27*R27+W27*X27+AC27*AD27+AI27*AJ27+AO27*AP27+AU27*AV27+BA27*BB27+BG27*BH27+BM27*BN27 -> 3000
A28: 21122 | B28: 46018 | C28: BR | D28: No | E28: TMK | F28: Chikanayakanahalli | G28: Mylara traders | H28: Chikanayakanahalli | J28: AG | K28: 2000 | L28: 1 | M28: Y | N28: 3L | O28: 4.2 | P28: AG | Q28: 1000 | R28: 2 | S28: W | T28: 3L | U28: 4.2 | V28: AG | W28: 1000 | X28: 1 | Y28: Y | Z28: 3L | AA28: 4.2 | AB28: AG | AC28: 750 | AD28: 1 | AE28: Y | AF28: 3L | AG28: 4.2 | AH28: AG | AI28: 750 | AJ28: 1 | AK28: W | AL28: 3L | AM28: 4.2 | BR28: COD | BT28: =K28*L28+Q28*R28+W28*X28+AC28*AD28+AI28*AJ28+AO28*AP28+AU28*AV28+BA28*BB28+BG28*BH28+BM28*BN28 -> 6500
A29: 21230 | B29: 46023 | C29: RP | D29: No | E29: TMK | F29: N R Tmk 01 | G29: Indian pipes&Hw | H29: Tumkur | I29: 0.40 Cod | J29: AG | K29: 750 | L29: 5 | M29: W | N29: 3L | O29: 3.7 | P29: AG | Q29: 1000 | R29: 1 | S29: W | T29: 3L | U29: 3.7 | BR29: 7 days | BT29: =K29*L29+Q29*R29+W29*X29+AC29*AD29+AI29*AJ29+AO29*AP29+AU29*AV29+BA29*BB29+BG29*BH29+BM29*BN29 -> 4750
BJ30: =J30*K30+O30*P30+T30*U30+Y30*Z30+AD30*AE30+AI30*AJ30+AN30*AO30+AS30*AT30+AX30*AY30+BC30*BD30 -> 0
BJ31: =J31*K31+O31*P31+T31*U31+Y31*Z31+AD31*AE31+AI31*AJ31+AN31*AO31+AS31*AT31+AX31*AY31+BC31*BD31 -> 0
BJ32: =J32*K32+O32*P32+T32*U32+Y32*Z32+AD32*AE32+AI32*AJ32+AN32*AO32+AS32*AT32+AX32*AY32+BC32*BD32 -> 0
BJ33: =J33*K33+O33*P33+T33*U33+Y33*Z33+AD33*AE33+AI33*AJ33+AN33*AO33+AS33*AT33+AX33*AY33+BC33*BD33 -> 0
BJ34: =J34*K34+O34*P34+T34*U34+Y34*Z34+AD34*AE34+AI34*AJ34+AN34*AO34+AS34*AT34+AX34*AY34+BC34*BD34 -> 0
BJ35: =J35*K35+O35*P35+T35*U35+Y35*Z35+AD35*AE35+AI35*AJ35+AN35*AO35+AS35*AT35+AX35*AY35+BC35*BD35 -> 0
BJ36: =J36*K36+O36*P36+T36*U36+Y36*Z36+AD36*AE36+AI36*AJ36+AN36*AO36+AS36*AT36+AX36*AY36+BC36*BD36 -> 0
BJ37: =J37*K37+O37*P37+T37*U37+Y37*Z37+AD37*AE37+AI37*AJ37+AN37*AO37+AS37*AT37+AX37*AY37+BC37*BD37 -> 0
BJ38: =J38*K38+O38*P38+T38*U38+Y38*Z38+AD38*AE38+AI38*AJ38+AN38*AO38+AS38*AT38+AX38*AY38+BC38*BD38 -> 0
BJ39: =J39*K39+O39*P39+T39*U39+Y39*Z39+AD39*AE39+AI39*AJ39+AN39*AO39+AS39*AT39+AX39*AY39+BC39*BD39 -> 0
BJ40: =J40*K40+O40*P40+T40*U40+Y40*Z40+AD40*AE40+AI40*AJ40+AN40*AO40+AS40*AT40+AX40*AY40+BC40*BD40 -> 0
...

Sheet PENDING
A1: ROUTE | B1: Route | C1: LTRS.
A2: ROUTE 1 | B2: R1 | C2: =SUMIF(ORDERS!$E:$E,PENDING!B2,ORDERS!$BT:$BT) -> 15500
A3: ROUTE 2 | B3: R2 | C3: =SUMIF(ORDERS!$E:$E,PENDING!B3,ORDERS!$BT:$BT) -> 14000
A4: ROUTE 3 | B4: R3 | C4: =SUMIF(ORDERS!$E:$E,PENDING!B4,ORDERS!$BT:$BT) -> 2500
A5: ROUTE 5 | B5: R5 | C5: =SUMIF(ORDERS!$E:$E,PENDING!B5,ORDERS!$BT:$BT) -> 6500
A6: ROUTE 6 | B6: R6 | C6: =SUMIF(ORDERS!$E:$E,PENDING!B6,ORDERS!$BT:$BT) -> 0
A7: ROUTE 7 | B7: R7 | C7: =SUMIF(ORDERS!$E:$E,PENDING!B7,ORDERS!$BT:$BT) -> 2000
A8: ROUTE 8 | B8: R8 | C8: =SUMIF(ORDERS!$E:$E,PENDING!B8,ORDERS!$BT:$BT) -> 3000
A9: AP | B9: AP | C9: =SUMIF(ORDERS!$E:$E,PENDING!B9,ORDERS!$BT:$BT) -> 0 | E9: LOCAL | F9: =SUM(C2:C8,C22) -> 43500
A10: BALLARY | B10: Ball | C10: =SUMIF(ORDERS!$E:$E,PENDING!B10,ORDERS!$BT:$BT) -> 9500 | E10: OUTSTATION | F10: =SUM(C9:C21)-C14 -> 35250
A11: DAVANGERE | B11: Dave | C11: =SUMIF(ORDERS!$E:$E,PENDING!B11,ORDERS!$BT:$BT) -> 3500
A12: GAURIBIDANUR | B12: Gaur | C12: =SUMIF(ORDERS!$E:$E,PENDING!B12,ORDERS!$BT:$BT) -> 0 | E12: BANGALORE | F12: =C23-F13 -> 78750
A13: HASSAN | B13: Hass | C13: =SUMIF(ORDERS!$E:$E,PENDING!B13,ORDERS!$BT:$BT) -> 11000 | E13: HUBLI | F13: =C14 -> 35500
A14: HUBLI | B14: Hubli | C14: =SUMIF(ORDERS!$E:$E,PENDING!B14,ORDERS!$BT:$BT) -> 35500
A15: KOLLAR | B15: Kol | C15: =SUMIF(ORDERS!$E:$E,PENDING!B15,ORDERS!$BT:$BT) -> 0
A16: MANDYA | B16: Man | C16: =SUMIF(ORDERS!$E:$E,PENDING!B16,ORDERS!$BT:$BT) -> 0
A17: MANDYA CITY | B17: Mancity | C17: =SUMIF(ORDERS!$E:$E,PENDING!B17,ORDERS!$BT:$BT) -> 0
A18: MANGALORE | B18: Mang | C18: =SUMIF(ORDERS!$E:$E,PENDING!B18,ORDERS!$BT:$BT) -> 0
A19: SHIVMOGGA | B19: Shiv | C19: =SUMIF(ORDERS!$E:$E,PENDING!B19,ORDERS!$BT:$BT) -> 0
A20: TN | B20: TN | C20: =SUMIF(ORDERS!$E:$E,PENDING!B20,ORDERS!$BT:$BT) -> 0
A21: TUMKUR | B21: TMK | C21: =SUMIF(ORDERS!$E:$E,PENDING!B21,ORDERS!$BT:$BT) -> 11250
A22: OTHERS | B22: Others | C22: =SUMIF(ORDERS!$E:$E,PENDING!B22,ORDERS!$BT:$BT) -> 0
A23: TOTAL | C23: =SUM(C2:C22) -> 114250

Sheet OUTSTATION
A1: Order ID | B1: Date | C1: Sales | D1: New Party | E1: Route | F1: Party Code | G1: Party Name | H1: Area | I1: Remarks | J1: Tank | K1: Size | L1: Qty | M1: Col | N1: Lay | O1: Rate | P1: Tank | Q1: Size | R1: Qty | S1: Col | T1: Lay | U1: Rate | V1: Tank | W1: Size | X1: Qty | Y1: Col | Z1: Lay | AA1: Rate | AB1: Tank | AC1: Size | AD1: Qty | AE1: Col | AF1: Lay | AG1: Rate | AH1: Tank | AI1: Size | AJ1: Qty | AK1: Col | AL1: Lay | AM1: Rate | AN1: Tank | AO1: Size | AP1: Qty | AQ1: Col | AR1: Lay | AS1: Rate | AT1: Tank | AU1: Size | AV1: Qty | AW1: Col | AX1: Lay | AY1: Rate | AZ1: Tank | BA1: Size | BB1: Qty | BC1: Col | BD1: Lay | BE1: Rate | BF1: Tank | BG1: Size | BH1: Qty | BI1: Col | BJ1: Lay | BK1: Rate | BL1: Tank | BM1: Size | BN1: Qty | BO1: Col | BP1: Lay | BQ1: Rate | BR1: Terms | BS1: Site Delivery | BT1: Ltrs
T53: DATE | V53: 45999
H54: Tank | I54: Size | J54: Qty | K54: Col | L54: Lay | M54: Rate
H55: =#REF! -> #REF! | I55: =#REF! -> #REF! | J55: =#REF! -> #REF! | K55: =#REF! -> #REF! | L55: =#REF! -> #REF! | M55: =#REF! -> #REF!
H56: =J3 -> 0 | I56: =K3 -> 0 | J56: =L3 -> 0 | K56: =M3 -> 0 | L56: =N3 -> 0 | M56: =O3 -> 0
H57: =J4 -> 0 | I57: =K4 -> 0 | J57: =L4 -> 0 | K57: =M4 -> 0 | L57: =N4 -> 0 | M57: =O4 -> 0
H58: =J5 -> 0 | I58: =K5 -> 0 | J58: =L5 -> 0 | K58: =M5 -> 0 | L58: =N5 -> 0 | M58: =O5 -> 0
H59: =J6 -> 0 | I59: =K6 -> 0 | J59: =L6 -> 0 | K59: =M6 -> 0 | L59: =N6 -> 0 | M59: =O6 -> 0
H60: =J7 -> 0 | I60: =K7 -> 0 | J60: =L7 -> 0 | K60: =M7 -> 0 | L60: =N7 -> 0 | M60: =O7 -> 0
H61: =J8 -> 0 | I61: =K8 -> 0 | J61: =L8 -> 0 | K61: =M8 -> 0 | L61: =N8 -> 0 | M61: =O8 -> 0
H62: =J9 -> 0 | I62: =K9 -> 0 | J62: =L9 -> 0 | K62: =M9 -> 0 | L62: =N9 -> 0 | M62: =O9 -> 0
H63: =J10 -> 0 | I63: =K10 -> 0 | J63: =L10 -> 0 | K63: =M10 -> 0 | L63: =N10 -> 0 | M63: =O10 -> 0
H64: =J11 -> 0 | I64: =K11 -> 0 | J64: =L11 -> 0 | K64: =M11 -> 0 | L64: =N11 -> 0 | M64: =O11 -> 0
H65: =J12 -> 0 | I65: =K12 -> 0 | J65: =L12 -> 0 | K65: =M12 -> 0 | L65: =N12 -> 0 | M65: =O12 -> 0
H66: =J13 -> 0 | I66: =K13 -> 0 | J66: =L13 -> 0 | K66: =M13 -> 0 | L66: =N13 -> 0 | M66: =O13 -> 0
H67: =J14 -> 0 | I67: =K14 -> 0 | J67: =L14 -> 0 | K67: =M14 -> 0 | L67: =N14 -> 0 | M67: =O14 -> 0
... H105: =J52 -> 0 | I105: =K52 -> 0 | J105: =L52 -> 0 | K105: =M52 -> 0 | L105: =N52 -> 0 | M105: =O52 -> 0
H106: =#REF! -> #REF! | I106: =#REF! -> #REF! | J106: =#REF! -> #REF! | K106: =#REF! -> #REF! | L106: =#REF! -> #REF! | M106: =#REF! -> #REF!
H107: =P3 -> 0 | I107: =Q3 -> 0 | J107: =R3 -> 0 | K107: =S3 -> 0 | L107: =T3 -> 0 | M107: =U3 -> 0
H108: =P4 -> 0 | I108: =Q4 -> 0 | J108: =R4 -> 0 | K108: =S4 -> 0 | L108: =T4 -> 0 | M108: =U4 -> 0
H109: =P5 -> 0 | I109: =Q5 -> 0 | J109: =R5 -> 0 | K109: =S5 -> 0 | L109: =T5 -> 0 | M109: =U5 -> 0
H110: =P6 -> 0 | I110: =Q6 -> 0 | J110: =R6 -> 0 | K110: =S6 -> 0 | L110: =T6 -> 0 | M110: =U6 -> 0
H111: =P7 -> 0 | I111: =Q7 -> 0 | J111: =R7 -> 0 | K111: =S7 -> 0 | L111: =T7 -> 0 | M111: =U7 -> 0
H112: =P8 -> 0 | I112: =Q8 -> 0 | J112: =R8 -> 0 | K112: =S8 -> 0 | L112: =T8 -> 0 | M112: =U8 -> 0
H113: =P9 -> 0 | I113: =Q9 -> 0 | J113: =R9 -> 0 | K113: =S9 -> 0 | L113: =T9 -> 0 | M113: =U9 -> 0
H114: =P10 -> 0 | I114: =Q10 -> 0 | J114: =R10 -> 0 | K114: =S10 -> 0 | L114: =T10 -> 0 | M114: =U10 -> 0
H115: =P11 -> 0 | I115: =Q11 -> 0 | J115: =R11 -> 0 | K115: =S11 -> 0 | L115: =T11 -> 0 | M115: =U11 -> 0
H116: =P12 -> 0 | I116: =Q12 -> 0 | J116: =R12 -> 0 | K116: =S12 -> 0 | L116: =T12 -> 0 | M116: =U12 -> 0
H117: =P13 -> 0 | I117: =Q13 -> 0 | J117: =R13 -> 0 | K117: =S13 -> 0 | L117: =T13 -> 0 | M117: =U13 -> 0
H118: =P14 -> 0 | I118: =Q14 -> 0 | J118: =R14 -> 0 | K118: =S14 -> 0 | L118: =T14 -> 0 | M118: =U14 -> 0
... H156: =P52 -> 0 | I156: =Q52 -> 0 | J156: =R52 -> 0 | K156: =S52 -> 0 | L156: =T52 -> 0 | M156: =U52 -> 0
H157: =#REF! -> #REF! | I157: =#REF! -> #REF! | J157: =#REF! -> #REF! | K157: =#REF! -> #REF! | L157: =#REF! -> #REF! | M157: =#REF! -> #REF!
H158: =V3 -> 0 | I158: =W3 -> 0 | J158: =X3 -> 0 | K158: =Y3 -> 0 | L158: =Z3 -> 0 | M158: =AA3 -> 0
H159: =V4 -> 0 | I159: =W4 -> 0 | J159: =X4 -> 0 | K159: =Y4 -> 0 | L159: =Z4 -> 0 | M159: =AA4 -> 0
H160: =V5 -> 0 | I160: =W5 -> 0 | J160: =X5 -> 0 | K160: =Y5 -> 0 | L160: =Z5 -> 0 | M160: =AA5 -> 0
H161: =V6 -> 0 | I161: =W6 -> 0 | J161: =X6 -> 0 | K161: =Y6 -> 0 | L161: =Z6 -> 0 | M161: =AA6 -> 0
H162: =V7 -> 0 | I162: =W7 -> 0 | J162: =X7 -> 0 | K162: =Y7 -> 0 | L162: =Z7 -> 0 | M162: =AA7 -> 0
H163: =V8 -> 0 | I163: =W8 -> 0 | J163: =X8 -> 0 | K163: =Y8 -> 0 | L163: =Z8 -> 0 | M163: =AA8 -> 0
H164: =V9 -> 0 | I164: =W9 -> 0 | J164: =X9 -> 0 | K164: =Y9 -> 0 | L164: =Z9 -> 0 | M164: =AA9 -> 0
H165: =V10 -> 0 | I165: =W10 -> 0 | J165: =X10 -> 0 | K165: =Y10 -> 0 | L165: =Z10 -> 0 | M165: =AA10 -> 0
...

Sheet LOCAL
A1: Order ID | B1: Date | C1: Sales | D1: New Party | E1: Route | F1: Party Code | G1: Party Name | H1: Area | I1: Remarks | J1: Tank | K1: Size | L1: Qty | M1: Col | N1: Lay | O1: Rate | P1: Tank | Q1: Size | R1: Qty | S1: Col | T1: Lay | U1: Rate | V1: Tank | W1: Size | X1: Qty | Y1: Col | Z1: Lay | AA1: Rate | AB1: Tank | AC1: Size | AD1: Qty | AE1: Col | AF1: Lay | AG1: Rate | AH1: Tank | AI1: Size | AJ1: Qty | AK1: Col | AL1: Lay | AM1: Rate | AN1: Tank | AO1: Size | AP1: Qty | AQ1: Col | AR1: Lay | AS1: Rate | AT1: Tank | AU1: Size | AV1: Qty | AW1: Col | AX1: Lay | AY1: Rate | AZ1: Tank | BA1: Size | BB1: Qty | BC1: Col | BD1: Lay | BE1: Rate | BF1: Tank | BG1: Size | BH1: Qty | BI1: Col | BJ1: Lay | BK1: Rate | BL1: Tank | BM1: Size | BN1: Qty | BO1: Col | BP1: Lay | BQ1: Rate | BR1: Terms | BS1: Site Delivery | BT1: Ltrs
T53: DATE | V53: 45999
H54: Tank | I54: Size | J54: Qty | K54: Col | L54: Lay | M54: Rate
H55: =#REF! -> #REF! | I55: =#REF! -> #REF! | J55: =#REF! -> #REF! | K55: =#REF! -> #REF! | L55: =#REF! -> #REF! | M55: =#REF! -> #REF!
H56: =J3 -> 0 | I56: =K3 -> 0 | J56: =L3 -> 0 | K56: =M3 -> 0 | L56: =N3 -> 0 | M56: =O3 -> 0
H57: =J4 -> 0 | I57: =K4 -> 0 | J57: =L4 -> 0 | K57: =M4 -> 0 | L57: =N4 -> 0 | M57: =O4 -> 0
H58: =J5 -> 0 | I58: =K5 -> 0 | J58: =L5 -> 0 | K58: =M5 -> 0 | L58: =N5 -> 0 | M58: =O5 -> 0
H59: =J6 -> 0 | I59: =K6 -> 0 | J59: =L6 -> 0 | K59: =M6 -> 0 | L59: =N6 -> 0 | M59: =O6 -> 0
H60: =J7 -> 0 | I60: =K7 -> 0 | J60: =L7 -> 0 | K60: =M7 -> 0 | L60: =N7 -> 0 | M60: =O7 -> 0
H61: =J8 -> 0 | I61: =K8 -> 0 | J61: =L8 -> 0 | K61: =M8 -> 0 | L61: =N8 -> 0 | M61: =O8 -> 0
H62: =J9 -> 0 | I62: =K9 -> 0 | J62: =L9 -> 0 | K62: =M9 -> 0 | L62: =N9 -> 0 | M62: =O9 -> 0
H63: =J10 -> 0 | I63: =K10 -> 0 | J63: =L10 -> 0 | K63: =M10 -> 0 | L63: =N10 -> 0 | M63: =O10 -> 0
H64: =J11 -> 0 | I64: =K11 -> 0 | J64: =L11 -> 0 | K64: =M11 -> 0 | L64: =N11 -> 0 | M64: =O11 -> 0
H65: =J12 -> 0 | I65: =K12 -> 0 | J65: =L12 -> 0 | K65: =M12 -> 0 | L65: =N12 -> 0 | M65: =O12 -> 0
H66: =J13 -> 0 | I66: =K13 -> 0 | J66: =L13 -> 0 | K66: =M13 -> 0 | L66: =N13 -> 0 | M66: =O13 -> 0
H67: =J14 -> 0 | I67: =K14 -> 0 | J67: =L14 -> 0 | K67: =M14 -> 0 | L67: =N14 -> 0 | M67: =O14 -> 0
... H105: =J52 -> 0 | I105: =K52 -> 0 | J105: =L52 -> 0 | K105: =M52 -> 0 | L105: =N52 -> 0 | M105: =O52 -> 0
H106: =#REF! -> #REF! | I106: =#REF! -> #REF! | J106: =#REF! -> #REF! | K106: =#REF! -> #REF! | L106: =#REF! -> #REF! | M106: =#REF! -> #REF!
H107: =P3 -> 0 | I107: =Q3 -> 0 | J107: =R3 -> 0 | K107: =S3 -> 0 | L107: =T3 -> 0 | M107: =U3 -> 0
H108: =P4 -> 0 | I108: =Q4 -> 0 | J108: =R4 -> 0 | K108: =S4 -> 0 | L108: =T4 -> 0 | M108: =U4 -> 0
H109: =P5 -> 0 | I109: =Q5 -> 0 | J109: =R5 -> 0 | K109: =S5 -> 0 | L109: =T5 -> 0 | M109: =U5 -> 0
H110: =P6 -> 0 | I110: =Q6 -> 0 | J110: =R6 -> 0 | K110: =S6 -> 0 | L110: =T6 -> 0 | M110: =U6 -> 0
H111: =P7 -> 0 | I111: =Q7 -> 0 | J111: =R7 -> 0 | K111: =S7 -> 0 | L111: =T7 -> 0 | M111: =U7 -> 0
H112: =P8 -> 0 | I112: =Q8 -> 0 | J112: =R8 -> 0 | K112: =S8 -> 0 | L112: =T8 -> 0 | M112: =U8 -> 0
H113: =P9 -> 0 | I113: =Q9 -> 0 | J113: =R9 -> 0 | K113: =S9 -> 0 | L113: =T9 -> 0 | M113: =U9 -> 0
H114: =P10 -> 0 | I114: =Q10 -> 0 | J114: =R10 -> 0 | K114: =S10 -> 0 | L114: =T10 -> 0 | M114: =U10 -> 0
H115: =P11 -> 0 | I115: =Q11 -> 0 | J115: =R11 -> 0 | K115: =S11 -> 0 | L115: =T11 -> 0 | M115: =U11 -> 0
H116: =P12 -> 0 | I116: =Q12 -> 0 | J116: =R12 -> 0 | K116: =S12 -> 0 | L116: =T12 -> 0 | M116: =U12 -> 0
H117: =P13 -> 0 | I117: =Q13 -> 0 | J117: =R13 -> 0 | K117: =S13 -> 0 | L117: =T13 -> 0 | M117: =U13 -> 0
H118: =P14 -> 0 | I118: =Q14 -> 0 | J118: =R14 -> 0 | K118: =S14 -> 0 | L118: =T14 -> 0 | M118: =U14 -> 0
... H156: =P52 -> 0 | I156: =Q52 -> 0 | J156: =R52 -> 0 | K156: =S52 -> 0 | L156: =T52 -> 0 | M156: =U52 -> 0
H157: =#REF! -> #REF! | I157: =#REF! -> #REF! | J157: =#REF! -> #REF! | K157: =#REF! -> #REF! | L157: =#REF! -> #REF! | M157: =#REF! -> #REF!
H158: =V3 -> 0 | I158: =W3 -> 0 | J158: =X3 -> 0 | K158: =Y3 -> 0 | L158: =Z3 -> 0 | M158: =AA3 -> 0
H159: =V4 -> 0 | I159: =W4 -> 0 | J159: =X4 -> 0 | K159: =Y4 -> 0 | L159: =Z4 -> 0 | M159: =AA4 -> 0
H160: =V5 -> 0 | I160: =W5 -> 0 | J160: =X5 -> 0 | K160: =Y5 -> 0 | L160: =Z5 -> 0 | M160: =AA5 -> 0
H161: =V6 -> 0 | I161: =W6 -> 0 | J161: =X6 -> 0 | K161: =Y6 -> 0 | L161: =Z6 -> 0 | M161: =AA6 -> 0
H162: =V7 -> 0 | I162: =W7 -> 0 | J162: =X7 -> 0 | K162: =Y7 -> 0 | L162: =Z7 -> 0 | M162: =AA7 -> 0
H163: =V8 -> 0 | I163: =W8 -> 0 | J163: =X8 -> 0 | K163: =Y8 -> 0 | L163: =Z8 -> 0 | M163: =AA8 -> 0
H164: =V9 -> 0 | I164: =W9 -> 0 | J164: =X9 -> 0 | K164: =Y9 -> 0 | L164: =Z9 -> 0 | M164: =AA9 -> 0
H165: =V10 -> 0 | I165: =W10 -> 0 | J165: =X10 -> 0 | K165: =Y10 -> 0 | L165: =Z10 -> 0 | M165: =AA10 -> 0
...

Sheet SLIP
A1: Order ID | B1: Date | C1: Sales | D1: New Party | E1: Route | F1: Party Code | G1: Party Name | H1: Area | I1: Remarks | J1: Tank | K1: Size | L1: Qty | M1: Col | N1: Lay | O1: Rate | P1: Tank | Q1: Size | R1: Qty | S1: Col | T1: Lay | U1: Rate | V1: Tank | W1: Size | X1: Qty | Y1: Col | Z1: Lay | AA1: Rate | AB1: Tank | AC1: Size | AD1: Qty | AE1: Col | AF1: Lay | AG1: Rate | AH1: Tank | AI1: Size | AJ1: Qty | AK1: Col | AL1: Lay | AM1: Rate | AN1: Tank | AO1: Size | AP1: Qty | AQ1: Col | AR1: Lay | AS1: Rate | AT1: Tank | AU1: Size | AV1: Qty | AW1: Col | AX1: Lay | AY1: Rate | AZ1: Tank | BA1: Size | BB1: Qty | BC1: Col | BD1: Lay | BE1: Rate | BF1: Tank | BG1: Size | BH1: Qty | BI1: Col | BJ1: Lay | BK1: Rate | BL1: Tank | BM1: Size | BN1: Qty | BO1: Col | BP1: Lay | BQ1: Rate | BR1: Terms | BS1: Site Delivery | BT1: Ltrs
A2: 1 | B2: 46006 | C2: KD | D2: No | E2: AP | F2: AP01 | G2: PAWAN PUTRA AGENCY 1 | H2: TIRUPATHI 1 | J2: AG | K2: 1000 | L2: 20 | M2: Y | N2: 3L | O2: 3.5 | P2: Pure | Q2: 750 | R2: 12 | S2: Y | T2: 3L | U2: 3.5 | V2: Loft | W2: 500 | X2: 13 | AA2: 3.5 | AB2: UT | AC2: 1000 | AD2: 2 | AG2: 3.5 | AH2: HT | AI2: 2000 | AJ2: 1 | AK2: Y | AL2: 3L | AM2: 3.5 | AN2: CAP | AP2: 15 | AQ2: W | BR2: COD | BS2: 3L-0.50&3000-0.60 | BT2: =K2*L2+Q2*R2+W2*X2+AC2*AD2+AI2*AJ2+AO2*AP2+AU2*AV2+BA2*BB2+BG2*BH2+BM2*BN2 -> 39500
A3: 2 | B3: 46006 | C3: KD | D3: No | E3: AP | F3: AP02 | G3: PAWAN PUTRA AGENCY 2 | H3: TIRUPATHI 2 | J3: AG | K3: 1000 | L3: 20 | M3: Y | N3: 3L | O3: 3.5 | P3: Pure | Q3: 750 | R3: 12 | S3: Y | T3: 3L | U3: 3.5 | V3: Loft | W3: 500 | X3: 13 | AA3: 3.5 | AB3: UT | AC3: 1000 | AD3: 2 | AG3: 3.5 | AH3: HT | AI3: 2000 | AJ3: 1 | AK3: Y | AL3: 3L | AM3: 3.5 | AN3: CAP | AP3: 15 | AQ3: W | BR3: COD | BS3: 3L-0.50&3000-0.60 | BT3: =K3*L3+Q3*R3+W3*X3+AC3*AD3+AI3*AJ3+AO3*AP3+AU3*AV3+BA3*BB3+BG3*BH3+BM3*BN3 -> 39500
A4: 3 | B4: 46006 | C4: KD | D4: No | E4: AP | F4: AP03 | G4: PAWAN PUTRA AGENCY 3 | H4: TIRUPATHI 3 | J4: AG | K4: 1000 | L4: 20 | M4: Y | N4: 3L | O4: 3.5 | P4: Pure | Q4: 750 | R4: 12 | S4: Y | T4: 3L | U4: 3.5 | V4: Loft | W4: 500 | X4: 13 | AA4: 3.5 | AB4: UT | AC4: 1000 | AD4: 2 | AG4: 3.5 | AH4: HT | AI4: 2000 | AJ4: 1 | AK4: Y | AL4: 3L | AM4: 3.5 | AN4: CAP | AP4: 15 | AQ4: W | BR4: COD | BS4: 3L-0.50&3000-0.60 | BT4: =K4*L4+Q4*R4+W4*X4+AC4*AD4+AI4*AJ4+AO4*AP4+AU4*AV4+BA4*BB4+BG4*BH4+BM4*BN4 -> 39500
A5: 4 | B5: 46006 | C5: KD | D5: No | E5: AP | F5: AP04 | G5: PAWAN PUTRA AGENCY 4 | H5: TIRUPATHI 4 | J5: AG | K5: 1000 | L5: 20 | M5: Y | N5: 3L | O5: 3.5 | P5: Pure | Q5: 750 | R5: 12 | S5: Y | T5: 3L | U5: 3.5 | V5: Loft | W5: 500 | X5: 13 | AA5: 3.5 | AB5: UT | AC5: 1000 | AD5: 2 | AG5: 3.5 | AH5: HT | AI5: 2000 | AJ5: 1 | AK5: Y | AL5: 3L | AM5: 3.5 | AN5: CAP | AP5: 15 | AQ5: W | BR5: COD | BS5: 3L-0.50&3000-0.60 | BT5: =K5*L5+Q5*R5+W5*X5+AC5*AD5+AI5*AJ5+AO5*AP5+AU5*AV5+BA5*BB5+BG5*BH5+BM5*BN5 -> 39500
A6: 5 | B6: 46006 | C6: KD | D6: No | E6: AP | F6: AP05 | G6: PAWAN PUTRA AGENCY 5 | H6: TIRUPATHI 5 | J6: AG | K6: 1000 | L6: 20 | M6: Y | N6: 3L | O6: 3.5 | P6: Pure | Q6: 750 | R6: 12 | S6: Y | T6: 3L | U6: 3.5 | V6: Loft | W6: 500 | X6: 13 | AA6: 3.5 | AB6: UT | AC6: 1000 | AD6: 2 | AG6: 3.5 | AH6: HT | AI6: 2000 | AJ6: 1 | AK6: Y | AL6: 3L | AM6: 3.5 | AN6: CAP | AP6: 15 | AQ6: W | BR6: COD | BS6: 3L-0.50&3000-0.60 | BT6: =K6*L6+Q6*R6+W6*X6+AC6*AD6+AI6*AJ6+AO6*AP6+AU6*AV6+BA6*BB6+BG6*BH6+BM6*BN6 -> 39500
A7: 6 | B7: 46006 | C7: KD | D7: No | E7: AP | F7: AP06 | G7: PAWAN PUTRA AGENCY 6 | H7: TIRUPATHI 6 | J7: AG | K7: 1000 | L7: 20 | M7: Y | N7: 3L | O7: 3.5 | P7: Pure | Q7: 750 | R7: 12 | S7: Y | T7: 3L | U7: 3.5 | V7: Loft | W7: 500 | X7: 13 | AA7: 3.5 | AB7: UT | AC7: 1000 | AD7: 2 | AG7: 3.5 | AH7: HT | AI7: 2000 | AJ7: 1 | AK7: Y | AL7: 3L | AM7: 3.5 | AN7: CAP | AP7: 15 | AQ7: W | BR7: COD | BS7: 3L-0.50&3000-0.60 | BT7: =K7*L7+Q7*R7+W7*X7+AC7*AD7+AI7*AJ7+AO7*AP7+AU7*AV7+BA7*BB7+BG7*BH7+BM7*BN7 -> 39500
A8: 7 | B8: 46006 | C8: KD | D8: No | E8: AP | F8: AP07 | G8: PAWAN PUTRA AGENCY 7 | H8: TIRUPATHI 7 | J8: AG | K8: 1000 | L8: 20 | M8: Y | N8: 3L | O8: 3.5 | P8: Pure | Q8: 750 | R8: 12 | S8: Y | T8: 3L | U8: 3.5 | V8: Loft | W8: 500 | X8: 13 | AA8: 3.5 | AB8: UT | AC8: 1000 | AD8: 2 | AG8: 3.5 | AH8: HT | AI8: 2000 | AJ8: 1 | AK8: Y | AL8: 3L | AM8: 3.5 | AN8: CAP | AP8: 15 | AQ8: W | BR8: COD | BS8: 3L-0.50&3000-0.60 | BT8: =K8*L8+Q8*R8+W8*X8+AC8*AD8+AI8*AJ8+AO8*AP8+AU8*AV8+BA8*BB8+BG8*BH8+BM8*BN8 -> 39500
A9: 8 | B9: 46006 | C9: KD | D9: No | E9: AP | F9: AP08 | G9: PAWAN PUTRA AGENCY 8 | H9: TIRUPATHI 8 | J9: AG | K9: 1000 | L9: 20 | M9: Y | N9: 3L | O9: 3.5 | P9: Pure | Q9: 750 | R9: 12 | S9: Y | T9: 3L | U9: 3.5 | V9: Loft | W9: 500 | X9: 13 | AA9: 3.5 | AB9: UT | AC9: 1000 | AD9: 2 | AG9: 3.5 | AH9: HT | AI9: 2000 | AJ9: 1 | AK9: Y | AL9: 3L | AM9: 3.5 | AN9: CAP | AP9: 15 | AQ9: W | BR9: COD | BS9: 3L-0.50&3000-0.60 | BT9: =K9*L9+Q9*R9+W9*X9+AC9*AD9+AI9*AJ9+AO9*AP9+AU9*AV9+BA9*BB9+BG9*BH9+BM9*BN9 -> 39500
A10: 9 | B10: 46006 | C10: KD | D10: No | E10: AP | F10: AP09 | G10: PAWAN PUTRA AGENCY 9 | H10: TIRUPATHI 9 | J10: AG | K10: 1000 | L10: 20 | M10: Y | N10: 3L | O10: 3.5 | P10: Pure | Q10: 750 | R10: 12 | S10: Y | T10: 3L | U10: 3.5 | V10: Loft | W10: 500 | X10: 13 | AA10: 3.5 | AB10: UT | AC10: 1000 | AD10: 2 | AG10: 3.5 | AH10: HT | AI10: 2000 | AJ10: 1 | AK10: Y | AL10: 3L | AM10: 3.5 | AN10: CAP | AP10: 15 | AQ10: W | BR10: COD | BS10: 3L-0.50&3000-0.60 | BT10: =K10*L10+Q10*R10+W10*X10+AC10*AD10+AI10*AJ10+AO10*AP10+AU10*AV10+BA10*BB10+BG10*BH10+BM10*BN10 -> 39500
A11: 10 | B11: 46006 | C11: KD | D11: No | E11: AP | F11: AP10 | G11: PAWAN PUTRA AGENCY 10 | H11: TIRUPATHI 10 | J11: AG | K11: 1000 | L11: 20 | M11: Y | N11: 3L | O11: 3.5 | P11: Pure | Q11: 750 | R11: 12 | S11: Y | T11: 3L | U11: 3.5 | V11: Loft | W11: 500 | X11: 13 | AA11: 3.5 | AB11: UT | AC11: 1000 | AD11: 2 | AG11: 3.5 | AH11: HT | AI11: 2000 | AJ11: 1 | AK11: Y | AL11: 3L | AM11: 3.5 | AN11: CAP | AP11: 15 | AQ11: W | BR11: COD | BS11: 3L-0.50&3000-0.60 | BT11: =K11*L11+Q11*R11+W11*X11+AC11*AD11+AI11*AJ11+AO11*AP11+AU11*AV11+BA11*BB11+BG11*BH11+BM11*BN11 -> 39500
I14: =I2 -> 0 | J14: =J2 -> AG | K14: =K2 -> 1000 | L14: =L2 -> 20 | M14: =M2 -> Y | P14: =M2 -> Y | Q14: =N2 -> 3L | R14: =R2 -> 12 | S14: =S2 -> Y | T14: =W2 -> 500 | U14: =X2 -> 13 | V14: =AB2 -> UT | W14: =AC2 -> 1000 | X14: =AG2 -> 3.5 | Y14: =AH2 -> HT | Z14: =AL2 -> 3L | AA14: =AM2 -> 3.5 | AB14: =AQ2 -> W | AC14: =AR2 -> 0 | AD14: =AV2 -> 0 | AE14: =AW2 -> 0 | AF14: =BA2 -> 0 | AG14: =BB2 -> 0 | AH14: =BF2 -> 0 | AI14: =BG2 -> 0 | AK14: 1 | AL14: =IF($P$14="3L",$Q$14,IF($R$14="3L",$S$14,IF($T$14="3L",$U$14,IF($V$14="3L",$W$14,IF($X$14="3L",$Y$14,IF($Z$14="3L",$AA$14,IF($AB$14="3L",$AC$14,IF($AD$14="3L",$AE$14,IF($AF$14="3L",$AG$14,IF($AH$14="3L",$AI$14,"")))))))))) -> 3.5 | AM14: =IF($P$14="4L",$Q$14,IF($R$14="4L",$S$14,IF($T$14="4L",$U$14,IF($V$14="4L",$W$14,IF($X$14="4L",$Y$14,IF($Z$14="4L",$AA$14,IF($AB$14="4L",$AC$14,IF($AD$14="4L",$AE$14,IF($AF$14="4L",$AG$14,IF($AH$14="4L",$AI$14,"")))))))))) | AN14: =IF($P$14="5L",$Q$14,IF($R$14="5L",$S$14,IF($T$14="5L",$U$14,IF($V$14="5L",$W$14,IF($X$14="5L",$Y$14,IF($Z$14="5L",$AA$14,IF($AB$14="5L",$AC$14,IF($AD$14="5L",$AE$14,IF($AF$14="5L",$AG$14,IF($AH$14="5L",$AI$14,"")))))))))) | AO14: =IF($P$14="FUM",$Q$14,IF($R$14="FUM",$S$14,IF($T$14="FUM",$U$14,IF($V$14="FUM",$W$14,IF($X$14="FUM",$Y$14,IF($Z$14="FUM",$AA$14,IF($AB$14="FUM",$AC$14,IF($AD$14="FUM",$AE$14,IF($AF$14="FUM",$AG$14,IF($AH$14="FUM",$AI$14,"")))))))))) | AP14: =IF($P$14="PURE",$Q$14,IF($R$14="PURE",$S$14,IF($T$14="PURE",$U$14,IF($V$14="PURE",$W$14,IF($X$14="PURE",$Y$14,IF($Z$14="PURE",$AA$14,IF($AB$14="PURE",$AC$14,IF($AD$14="PURE",$AE$14,IF($AF$14="PURE",$AG$14,IF($AH$14="PURE",$AI$14,""))))))))))
I15: =I3 -> 0 | J15: =J3 -> AG | K15: =K3 -> 1000 | L15: =L3 -> 20 | M15: =M3 -> Y | P15: =M3 -> Y | Q15: =N3 -> 3L | R15: =R3 -> 12 | S15: =S3 -> Y | T15: =W3 -> 500 | U15: =X3 -> 13 | V15: =AB3 -> UT | W15: =AC3 -> 1000 | X15: =AG3 -> 3.5 | Y15: =AH3 -> HT | Z15: =AL3 -> 3L | AA15: =AM3 -> 3.5 | AB15: =AQ3 -> W | AC15: =AR3 -> 0 | AD15: =AV3 -> 0 | AE15: =AW3 -> 0 | AF15: =BA3 -> 0 | AG15: =BB3 -> 0 | AH15: =BF3 -> 0 | AI15: =BG3 -> 0 | AK15: 2 | AL15: =IF($P$15="3L",$Q$15,IF($R$15="3L",$S$15,IF($T$15="3L",$U$15,IF($V$15="3L",$W$15,IF($X$15="3L",$Y$15,IF($Z$15="3L",$AA$15,IF($AB$15="3L",$AC$15,IF($AD$15="3L",$AE$15,IF($AF$15="3L",$AG$15,IF($AH$15="3L",$AI$15,"")))))))))) -> 3.5 | AM15: =IF($P$15="4L",$Q$15,IF($R$15="4L",$S$15,IF($T$15="4L",$U$15,IF($V$15="4L",$W$15,IF($X$15="4L",$Y$15,IF($Z$15="4L",$AA$15,IF($AB$15="4L",$AC$15,IF($AD$15="4L",$AE$15,IF($AF$15="4L",$AG$15,IF($AH$15="4L",$AI$15,"")))))))))) | AN15: =IF($P$15="5L",$Q$15,IF($R$15="5L",$S$15,IF($T$15="5L",$U$15,IF($V$15="5L",$W$15,IF($X$15="5L",$Y$15,IF($Z$15="5L",$AA$15,IF($AB$15="5L",$AC$15,IF($AD$15="5L",$AE$15,IF($AF$15="5L",$AG$15,IF($AH$15="5L",$AI$15,"")))))))))) | AO15: =IF($P$15="FUM",$Q$15,IF($R$15="FUM",$S$15,IF($T$15="FUM",$U$15,IF($V$15="FUM",$W$15,IF($X$15="FUM",$Y$15,IF($Z$15="FUM",$AA$15,IF($AB$15="FUM",$AC$15,IF($AD$15="FUM",$AE$15,IF($AF$15="FUM",$AG$15,IF($AH$15="FUM",$AI$15,"")))))))))) | AP15: =IF($P$15="PURE",$Q$15,IF($R$15="PURE",$S$15,IF($T$15="PURE",$U$15,IF($V$15="PURE",$W$15,IF($X$15="PURE",$Y$15,IF($Z$15="PURE",$AA$15,IF($AB$15="PURE",$AC$15,IF($AD$15="PURE",$AE$15,IF($AF$15="PURE",$AG$15,IF($AH$15="PURE",$AI$15,""))))))))))
I16: =I4 -> 0 | J16: =J4 -> AG | K16: =K4 -> 1000 | L16: =L4 -> 20 | M16: =M4 -> Y | P16: =M4 -> Y | Q16: =N4 -> 3L | R16: =R4 -> 12 | S16: =S4 -> Y | T16: =W4 -> 500 | U16: =X4 -> 13 | V16: =AB4 -> UT | W16: =AC4 -> 1000 | X16: =AG4 -> 3.5 | Y16: =AH4 -> HT | Z16: =AL4 -> 3L | AA16: =AM4 -> 3.5 | AB16: =AQ4 -> W | AC16: =AR4 -> 0 | AD16: =AV4 -> 0 | AE16: =AW4 -> 0 | AF16: =BA4 -> 0 | AG16: =BB4 -> 0 | AH16: =BF4 -> 0 | AI16: =BG4 -> 0 | AK16: 3 | AL16: =IF($P$16="3L",$Q$16,IF($R$16="3L",$S$16,IF($T$16="3L",$U$16,IF($V$16="3L",$W$16,IF($X$16="3L",$Y$16,IF($Z$16="3L",$AA$16,IF($AB$16="3L",$AC$16,IF($AD$16="3L",$AE$16,IF($AF$16="3L",$AG$16,IF($AH$16="3L",$AI$16,"")))))))))) -> 3.5 | AM16: =IF($P$16="4L",$Q$16,IF($R$16="4L",$S$16,IF($T$16="4L",$U$16,IF($V$16="4L",$W$16,IF($X$16="4L",$Y$16,IF($Z$16="4L",$AA$16,IF($AB$16="4L",$AC$16,IF($AD$16="4L",$AE$16,IF($AF$16="4L",$AG$16,IF($AH$16="4L",$AI$16,"")))))))))) | AN16: =IF($P$16="5L",$Q$16,IF($R$16="5L",$S$16,IF($T$16="5L",$U$16,IF($V$16="5L",$W$16,IF($X$16="5L",$Y$16,IF($Z$16="5L",$AA$16,IF($AB$16="5L",$AC$16,IF($AD$16="5L",$AE$16,IF($AF$16="5L",$AG$16,IF($AH$16="5L",$AI$16,"")))))))))) | AO16: =IF($P$16="FUM",$Q$16,IF($R$16="FUM",$S$16,IF($T$16="FUM",$U$16,IF($V$16="FUM",$W$16,IF($X$16="FUM",$Y$16,IF($Z$16="FUM",$AA$16,IF($AB$16="FUM",$AC$16,IF($AD$16="FUM",$AE$16,IF($AF$16="FUM",$AG$16,IF($AH$16="FUM",$AI$16,"")))))))))) | AP16: =IF($P$16="PURE",$Q$16,IF($R$16="PURE",$S$16,IF($T$16="PURE",$U$16,IF($V$16="PURE",$W$16,IF($X$16="PURE",$Y$16,IF($Z$16="PURE",$AA$16,IF($AB$16="PURE",$AC$16,IF($AD$16="PURE",$AE$16,IF($AF$16="PURE",$AG$16,IF($AH$16="PURE",$AI$16,""))))))))))
I17: =I5 -> 0 | J17: =J5 -> AG | K17: =K5 -> 1000 | L17: =L5 -> 20 | M17: =M5 -> Y | P17: =M5 -> Y | Q17: =N5 -> 3L | R17: =R5 -> 12 | S17: =S5 -> Y | T17: =W5 -> 500 | U17: =X5 -> 13 | V17: =AB5 -> UT | W17: =AC5 -> 1000 | X17: =AG5 -> 3.5 | Y17: =AH5 -> HT | Z17: =AL5 -> 3L | AA17: =AM5 -> 3.5 | AB17: =AQ5 -> W | AC17: =AR5 -> 0 | AD17: =AV5 -> 0 | AE17: =AW5 -> 0 | AF17: =BA5 -> 0 | AG17: =BB5 -> 0 | AH17: =BF5 -> 0 | AI17: =BG5 -> 0 | AK17: 4 | AL17: =IF($P$17="3L",$Q$17,IF($R$17="3L",$S$17,IF($T$17="3L",$U$17,IF($V$17="3L",$W$17,IF($X$17="3L",$Y$17,IF($Z$17="3L",$AA$17,IF($AB$17="3L",$AC$17,IF($AD$17="3L",$AE$17,IF($AF$17="3L",$AG$17,IF($AH$17="3L",$AI$17,"")))))))))) -> 3.5 | AM17: =IF($P$17="4L",$Q$17,IF($R$17="4L",$S$17,IF($T$17="4L",$U$17,IF($V$17="4L",$W$17,IF($X$17="4L",$Y$17,IF($Z$17="4L",$AA$17,IF($AB$17="4L",$AC$17,IF($AD$17="4L",$AE$17,IF($AF$17="4L",$AG$17,IF($AH$17="4L",$AI$17,"")))))))))) | AN17: =IF($P$17="5L",$Q$17,IF($R$17="5L",$S$17,IF($T$17="5L",$U$17,IF($V$17="5L",$W$17,IF($X$17="5L",$Y$17,IF($Z$17="5L",$AA$17,IF($AB$17="5L",$AC$17,IF($AD$17="5L",$AE$17,IF($AF$17="5L",$AG$17,IF($AH$17="5L",$AI$17,"")))))))))) | AO17: =IF($P$17="FUM",$Q$17,IF($R$17="FUM",$S$17,IF($T$17="FUM",$U$17,IF($V$17="FUM",$W$17,IF($X$17="FUM",$Y$17,IF($Z$17="FUM",$AA$17,IF($AB$17="FUM",$AC$17,IF($AD$17="FUM",$AE$17,IF($AF$17="FUM",$AG$17,IF($AH$17="FUM",$AI$17,"")))))))))) | AP17: =IF($P$17="PURE",$Q$17,IF($R$17="PURE",$S$17,IF($T$17="PURE",$U$17,IF($V$17="PURE",$W$17,IF($X$17="PURE",$Y$17,IF($Z$17="PURE",$AA$17,IF($AB$17="PURE",$AC$17,IF($AD$17="PURE",$AE$17,IF($AF$17="PURE",$AG$17,IF($AH$17="PURE",$AI$17,""))))))))))
I18: =I6 -> 0 | J18: =J6 -> AG | K18: =K6 -> 1000 | L18: =L6 -> 20 | M18: =M6 -> Y | P18: =M6 -> Y | Q18: =N6 -> 3L | R18: =R6 -> 12 | S18: =S6 -> Y | T18: =W6 -> 500 | U18: =X6 -> 13 | V18: =AB6 -> UT | W18: =AC6 -> 1000 | X18: =AG6 -> 3.5 | Y18: =AH6 -> HT | Z18: =AL6 -> 3L | AA18: =AM6 -> 3.5 | AB18: =AQ6 -> W | AC18: =AR6 -> 0 | AD18: =AV6 -> 0 | AE18: =AW6 -> 0 | AF18: =BA6 -> 0 | AG18: =BB6 -> 0 | AH18: =BF6 -> 0 | AI18: =BG6 -> 0 | AK18: 5 | AL18: =IF($P$18="3L",$Q$18,IF($R$18="3L",$S$18,IF($T$18="3L",$U$18,IF($V$18="3L",$W$18,IF($X$18="3L",$Y$18,IF($Z$18="3L",$AA$18,IF($AB$18="3L",$AC$18,IF($AD$18="3L",$AE$18,IF($AF$18="3L",$AG$18,IF($AH$18="3L",$AI$18,"")))))))))) -> 3.5 | AM18: =IF($P$18="4L",$Q$18,IF($R$18="4L",$S$18,IF($T$18="4L",$U$18,IF($V$18="4L",$W$18,IF($X$18="4L",$Y$18,IF($Z$18="4L",$AA$18,IF($AB$18="4L",$AC$18,IF($AD$18="4L",$AE$18,IF($AF$18="4L",$AG$18,IF($AH$18="4L",$AI$18,"")))))))))) | AN18: =IF($P$18="5L",$Q$18,IF($R$18="5L",$S$18,IF($T$18="5L",$U$18,IF($V$18="5L",$W$18,IF($X$18="5L",$Y$18,IF($Z$18="5L",$AA$18,IF($AB$18="5L",$AC$18,IF($AD$18="5L",$AE$18,IF($AF$18="5L",$AG$18,IF($AH$18="5L",$AI$18,"")))))))))) | AO18: =IF($P$18="FUM",$Q$18,IF($R$18="FUM",$S$18,IF($T$18="FUM",$U$18,IF($V$18="FUM",$W$18,IF($X$18="FUM",$Y$18,IF($Z$18="FUM",$AA$18,IF($AB$18="FUM",$AC$18,IF($AD$18="FUM",$AE$18,IF($AF$18="FUM",$AG$18,IF($AH$18="FUM",$AI$18,"")))))))))) | AP18: =IF($P$18="PURE",$Q$18,IF($R$18="PURE",$S$18,IF($T$18="PURE",$U$18,IF($V$18="PURE",$W$18,IF($X$18="PURE",$Y$18,IF($Z$18="PURE",$AA$18,IF($AB$18="PURE",$AC$18,IF($AD$18="PURE",$AE$18,IF($AF$18="PURE",$AG$18,IF($AH$18="PURE",$AI$18,""))))))))))
I19: =I7 -> 0 | J19: =J7 -> AG | K19: =K7 -> 1000 | L19: =L7 -> 20 | M19: =M7 -> Y | P19: =M7 -> Y | Q19: =N7 -> 3L | R19: =R7 -> 12 | S19: =S7 -> Y | T19: =W7 -> 500 | U19: =X7 -> 13 | V19: =AB7 -> UT | W19: =AC7 -> 1000 | X19: =AG7 -> 3.5 | Y19: =AH7 -> HT | Z19: =AL7 -> 3L | AA19: =AM7 -> 3.5 | AB19: =AQ7 -> W | AC19: =AR7 -> 0 | AD19: =AV7 -> 0 | AE19: =AW7 -> 0 | AF19: =BA7 -> 0 | AG19: =BB7 -> 0 | AH19: =BF7 -> 0 | AI19: =BG7 -> 0 | AK19: 6 | AL19: =IF($P$19="3L",$Q$19,IF($R$19="3L",$S$19,IF($T$19="3L",$U$19,IF($V$19="3L",$W$19,IF($X$19="3L",$Y$19,IF($Z$19="3L",$AA$19,IF($AB$19="3L",$AC$19,IF($AD$19="3L",$AE$19,IF($AF$19="3L",$AG$19,IF($AH$19="3L",$AI$19,"")))))))))) -> 3.5 | AM19: =IF($P$19="4L",$Q$19,IF($R$19="4L",$S$19,IF($T$19="4L",$U$19,IF($V$19="4L",$W$19,IF($X$19="4L",$Y$19,IF($Z$19="4L",$AA$19,IF($AB$19="4L",$AC$19,IF($AD$19="4L",$AE$19,IF($AF$19="4L",$AG$19,IF($AH$19="4L",$AI$19,"")))))))))) | AN19: =IF($P$19="5L",$Q$19,IF($R$19="5L",$S$19,IF($T$19="5L",$U$19,IF($V$19="5L",$W$19,IF($X$19="5L",$Y$19,IF($Z$19="5L",$AA$19,IF($AB$19="5L",$AC$19,IF($AD$19="5L",$AE$19,IF($AF$19="5L",$AG$19,IF($AH$19="5L",$AI$19,"")))))))))) | AO19: =IF($P$19="FUM",$Q$19,IF($R$19="FUM",$S$19,IF($T$19="FUM",$U$19,IF($V$19="FUM",$W$19,IF($X$19="FUM",$Y$19,IF($Z$19="FUM",$AA$19,IF($AB$19="FUM",$AC$19,IF($AD$19="FUM",$AE$19,IF($AF$19="FUM",$AG$19,IF($AH$19="FUM",$AI$19,"")))))))))) | AP19: =IF($P$19="PURE",$Q$19,IF($R$19="PURE",$S$19,IF($T$19="PURE",$U$19,IF($V$19="PURE",$W$19,IF($X$19="PURE",$Y$19,IF($Z$19="PURE",$AA$19,IF($AB$19="PURE",$AC$19,IF($AD$19="PURE",$AE$19,IF($AF$19="PURE",$AG$19,IF($AH$19="PURE",$AI$19,""))))))))))
I20: =I8 -> 0 | J20: =J8 -> AG | K20: =K8 -> 1000 | L20: =L8 -> 20 | M20: =M8 -> Y | P20: =M8 -> Y | Q20: =N8 -> 3L | R20: =R8 -> 12 | S20: =S8 -> Y | T20: =W8 -> 500 | U20: =X8 -> 13 | V20: =AB8 -> UT | W20: =AC8 -> 1000 | X20: =AG8 -> 3.5 | Y20: =AH8 -> HT | Z20: =AL8 -> 3L | AA20: =AM8 -> 3.5 | AB20: =AQ8 -> W | AC20: =AR8 -> 0 | AD20: =AV8 -> 0 | AE20: =AW8 -> 0 | AF20: =BA8 -> 0 | AG20: =BB8 -> 0 | AH20: =BF8 -> 0 | AI20: =BG8 -> 0 | AK20: 7 | AL20: =IF($P$20="3L",$Q$20,IF($R$20="3L",$S$20,IF($T$20="3L",$U$20,IF($V$20="3L",$W$20,IF($X$20="3L",$Y$20,IF($Z$20="3L",$AA$20,IF($AB$20="3L",$AC$20,IF($AD$20="3L",$AE$20,IF($AF$20="3L",$AG$20,IF($AH$20="3L",$AI$20,"")))))))))) -> 3.5 | AM20: =IF($P$20="4L",$Q$20,IF($R$20="4L",$S$20,IF($T$20="4L",$U$20,IF($V$20="4L",$W$20,IF($X$20="4L",$Y$20,IF($Z$20="4L",$AA$20,IF($AB$20="4L",$AC$20,IF($AD$20="4L",$AE$20,IF($AF$20="4L",$AG$20,IF($AH$20="4L",$AI$20,"")))))))))) | AN20: =IF($P$20="5L",$Q$20,IF($R$20="5L",$S$20,IF($T$20="5L",$U$20,IF($V$20="5L",$W$20,IF($X$20="5L",$Y$20,IF($Z$20="5L",$AA$20,IF($AB$20="5L",$AC$20,IF($AD$20="5L",$AE$20,IF($AF$20="5L",$AG$20,IF($AH$20="5L",$AI$20,"")))))))))) | AO20: =IF($P$20="FUM",$Q$20,IF($R$20="FUM",$S$20,IF($T$20="FUM",$U$20,IF($V$20="FUM",$W$20,IF($X$20="FUM",$Y$20,IF($Z$20="FUM",$AA$20,IF($AB$20="FUM",$AC$20,IF($AD$20="FUM",$AE$20,IF($AF$20="FUM",$AG$20,IF($AH$20="FUM",$AI$20,"")))))))))) | AP20: =IF($P$20="PURE",$Q$20,IF($R$20="PURE",$S$20,IF($T$20="PURE",$U$20,IF($V$20="PURE",$W$20,IF($X$20="PURE",$Y$20,IF($Z$20="PURE",$AA$20,IF($AB$20="PURE",$AC$20,IF($AD$20="PURE",$AE$20,IF($AF$20="PURE",$AG$20,IF($AH$20="PURE",$AI$20,""))))))))))
I21: =I9 -> 0 | J21: =J9 -> AG | K21: =K9 -> 1000 | L21: =L9 -> 20 | M21: =M9 -> Y | P21: =M9 -> Y | Q21: =N9 -> 3L | R21: =R9 -> 12 | S21: =S9 -> Y | T21: =W9 -> 500 | U21: =X9 -> 13 | V21: =AB9 -> UT | W21: =AC9 -> 1000 | X21: =AG9 -> 3.5 | Y21: =AH9 -> HT | Z21: =AL9 -> 3L | AA21: =AM9 -> 3.5 | AB21: =AQ9 -> W | AC21: =AR9 -> 0 | AD21: =AV9 -> 0 | AE21: =AW9 -> 0 | AF21: =BA9 -> 0 | AG21: =BB9 -> 0 | AH21: =BF9 -> 0 | AI21: =BG9 -> 0 | AK21: 8 | AL21: =IF($P$21="3L",$Q$21,IF($R$21="3L",$S$21,IF($T$21="3L",$U$21,IF($V$21="3L",$W$21,IF($X$21="3L",$Y$21,IF($Z$21="3L",$AA$21,IF($AB$21="3L",$AC$21,IF($AD$21="3L",$AE$21,IF($AF$21="3L",$AG$21,IF($AH$21="3L",$AI$21,"")))))))))) -> 3.5 | AM21: =IF($P$21="4L",$Q$21,IF($R$21="4L",$S$21,IF($T$21="4L",$U$21,IF($V$21="4L",$W$21,IF($X$21="4L",$Y$21,IF($Z$21="4L",$AA$21,IF($AB$21="4L",$AC$21,IF($AD$21="4L",$AE$21,IF($AF$21="4L",$AG$21,IF($AH$21="4L",$AI$21,"")))))))))) | AN21: =IF($P$21="5L",$Q$21,IF($R$21="5L",$S$21,IF($T$21="5L",$U$21,IF($V$21="5L",$W$21,IF($X$21="5L",$Y$21,IF($Z$21="5L",$AA$21,IF($AB$21="5L",$AC$21,IF($AD$21="5L",$AE$21,IF($AF$21="5L",$AG$21,IF($AH$21="5L",$AI$21,"")))))))))) | AO21: =IF($P$21="FUM",$Q$21,IF($R$21="FUM",$S$21,IF($T$21="FUM",$U$21,IF($V$21="FUM",$W$21,IF($X$21="FUM",$Y$21,IF($Z$21="FUM",$AA$21,IF($AB$21="FUM",$AC$21,IF($AD$21="FUM",$AE$21,IF($AF$21="FUM",$AG$21,IF($AH$21="FUM",$AI$21,"")))))))))) | AP21: =IF($P$21="PURE",$Q$21,IF($R$21="PURE",$S$21,IF($T$21="PURE",$U$21,IF($V$21="PURE",$W$21,IF($X$21="PURE",$Y$21,IF($Z$21="PURE",$AA$21,IF($AB$21="PURE",$AC$21,IF($AD$21="PURE",$AE$21,IF($AF$21="PURE",$AG$21,IF($AH$21="PURE",$AI$21,""))))))))))
I22: =I10 -> 0 | J22: =J10 -> AG | K22: =K10 -> 1000 | L22: =L10 -> 20 | M22: =M10 -> Y | P22: =M10 -> Y | Q22: =N10 -> 3L | R22: =R10 -> 12 | S22: =S10 -> Y | T22: =W10 -> 500 | U22: =X10 -> 13 | V22: =AB10 -> UT | W22: =AC10 -> 1000 | X22: =AG10 -> 3.5 | Y22: =AH10 -> HT | Z22: =AL10 -> 3L | AA22: =AM10 -> 3.5 | AB22: =AQ10 -> W | AC22: =AR10 -> 0 | AD22: =AV10 -> 0 | AE22: =AW10 -> 0 | AF22: =BA10 -> 0 | AG22: =BB10 -> 0 | AH22: =BF10 -> 0 | AI22: =BG10 -> 0 | AK22: 9 | AL22: =IF($P$22="3L",$Q$22,IF($R$22="3L",$S$22,IF($T$22="3L",$U$22,IF($V$22="3L",$W$22,IF($X$22="3L",$Y$22,IF($Z$22="3L",$AA$22,IF($AB$22="3L",$AC$22,IF($AD$22="3L",$AE$22,IF($AF$22="3L",$AG$22,IF($AH$22="3L",$AI$22,"")))))))))) -> 3.5 | AM22: =IF($P$22="4L",$Q$22,IF($R$22="4L",$S$22,IF($T$22="4L",$U$22,IF($V$22="4L",$W$22,IF($X$22="4L",$Y$22,IF($Z$22="4L",$AA$22,IF($AB$22="4L",$AC$22,IF($AD$22="4L",$AE$22,IF($AF$22="4L",$AG$22,IF($AH$22="4L",$AI$22,"")))))))))) | AN22: =IF($P$22="5L",$Q$22,IF($R$22="5L",$S$22,IF($T$22="5L",$U$22,IF($V$22="5L",$W$22,IF($X$22="5L",$Y$22,IF($Z$22="5L",$AA$22,IF($AB$22="5L",$AC$22,IF($AD$22="5L",$AE$22,IF($AF$22="5L",$AG$22,IF($AH$22="5L",$AI$22,"")))))))))) | AO22: =IF($P$22="FUM",$Q$22,IF($R$22="FUM",$S$22,IF($T$22="FUM",$U$22,IF($V$22="FUM",$W$22,IF($X$22="FUM",$Y$22,IF($Z$22="FUM",$AA$22,IF($AB$22="FUM",$AC$22,IF($AD$22="FUM",$AE$22,IF($AF$22="FUM",$AG$22,IF($AH$22="FUM",$AI$22,"")))))))))) | AP22: =IF($P$22="PURE",$Q$22,IF($R$22="PURE",$S$22,IF($T$22="PURE",$U$22,IF($V$22="PURE",$W$22,IF($X$22="PURE",$Y$22,IF($Z$22="PURE",$AA$22,IF($AB$22="PURE",$AC$22,IF($AD$22="PURE",$AE$22,IF($AF$22="PURE",$AG$22,IF($AH$22="PURE",$AI$22,""))))))))))
I23: =I11 -> 0 | J23: =J11 -> AG | K23: =K11 -> 1000 | L23: =L11 -> 20 | M23: =M11 -> Y | P23: =M11 -> Y | Q23: =N11 -> 3L | R23: =R11 -> 12 | S23: =S11 -> Y | T23: =W11 -> 500 | U23: =X11 -> 13 | V23: =AB11 -> UT | W23: =AC11 -> 1000 | X23: =AG11 -> 3.5 | Y23: =AH11 -> HT | Z23: =AL11 -> 3L | AA23: =AM11 -> 3.5 | AB23: =AQ11 -> W | AC23: =AR11 -> 0 | AD23: =AV11 -> 0 | AE23: =AW11 -> 0 | AF23: =BA11 -> 0 | AG23: =BB11 -> 0 | AH23: =BF11 -> 0 | AI23: =BG11 -> 0 | AK23: 10 | AL23: =IF($P$23="3L",$Q$23,IF($R$23="3L",$S$23,IF($T$23="3L",$U$23,IF($V$23="3L",$W$23,IF($X$23="3L",$Y$23,IF($Z$23="3L",$AA$23,IF($AB$23="3L",$AC$23,IF($AD$23="3L",$AE$23,IF($AF$23="3L",$AG$23,IF($AH$23="3L",$AI$23,"")))))))))) -> 3.5 | AM23: =IF($P$23="4L",$Q$23,IF($R$23="4L",$S$23,IF($T$23="4L",$U$23,IF($V$23="4L",$W$23,IF($X$23="4L",$Y$23,IF($Z$23="4L",$AA$23,IF($AB$23="4L",$AC$23,IF($AD$23="4L",$AE$23,IF($AF$23="4L",$AG$23,IF($AH$23="4L",$AI$23,"")))))))))) | AN23: =IF($P$23="5L",$Q$23,IF($R$23="5L",$S$23,IF($T$23="5L",$U$23,IF($V$23="5L",$W$23,IF($X$23="5L",$Y$23,IF($Z$23="5L",$AA$23,IF($AB$23="5L",$AC$23,IF($AD$23="5L",$AE$23,IF($AF$23="5L",$AG$23,IF($AH$23="5L",$AI$23,"")))))))))) | AO23: =IF($P$23="FUM",$Q$23,IF($R$23="FUM",$S$23,IF($T$23="FUM",$U$23,IF($V$23="FUM",$W$23,IF($X$23="FUM",$Y$23,IF($Z$23="FUM",$AA$23,IF($AB$23="FUM",$AC$23,IF($AD$23="FUM",$AE$23,IF($AF$23="FUM",$AG$23,IF($AH$23="FUM",$AI$23,"")))))))))) | AP23: =IF($P$23="PURE",$Q$23,IF($R$23="PURE",$S$23,IF($T$23="PURE",$U$23,IF($V$23="PURE",$W$23,IF($X$23="PURE",$Y$23,IF($Z$23="PURE",$AA$23,IF($AB$23="PURE",$AC$23,IF($AD$23="PURE",$AE$23,IF($AF$23="PURE",$AG$23,IF($AH$23="PURE",$AI$23,""))))))))))
I24: =N2 -> 3L | J24: =O2 -> 3.5 | K24: =P2 -> Pure | L24: =Q2 -> 750 | M24: =R2 -> 12
I25: =N3 -> 3L | J25: =O3 -> 3.5 | K25: =P3 -> Pure | L25: =Q3 -> 750 | M25: =R3 -> 12
I26: =N4 -> 3L | J26: =O4 -> 3.5 | K26: =P4 -> Pure | L26: =Q4 -> 750 | M26: =R4 -> 12
I27: =N5 -> 3L | J27: =O5 -> 3.5 | K27: =P5 -> Pure | L27: =Q5 -> 750 | M27: =R5 -> 12
I28: =N6 -> 3L | J28: =O6 -> 3.5 | K28: =P6 -> Pure | L28: =Q6 -> 750 | M28: =R6 -> 12
I29: =N7 -> 3L | J29: =O7 -> 3.5 | K29: =P7 -> Pure | L29: =Q7 -> 750 | M29: =R7 -> 12
I30: =N8 -> 3L | J30: =O8 -> 3.5 | K30: =P8 -> Pure | L30: =Q8 -> 750 | M30: =R8 -> 12
I31: =N9 -> 3L | J31: =O9 -> 3.5 | K31: =P9 -> Pure | L31: =Q9 -> 750 | M31: =R9 -> 12
I32: =N10 -> 3L | J32: =O10 -> 3.5 | K32: =P10 -> Pure | L32: =Q10 -> 750 | M32: =R10 -> 12
I33: =N11 -> 3L | J33: =O11 -> 3.5 | K33: =P11 -> Pure | L33: =Q11 -> 750 | M33: =R11 -> 12
I34: =S2 -> Y | J34: =T2 -> 3L | K34: =U2 -> 3.5 | L34: =V2 -> Loft | M34: =W2 -> 500
I35: =S3 -> Y | J35: =T3 -> 3L | K35: =U3 -> 3.5 | L35: =V3 -> Loft | M35: =W3 -> 500
I36: =S4 -> Y | J36: =T4 -> 3L | K36: =U4 -> 3.5 | L36: =V4 -> Loft | M36: =W4 -> 500
I37: =S5 -> Y | J37: =T5 -> 3L | K37: =U5 -> 3.5 | L37: =V5 -> Loft | M37: =W5 -> 500
I38: =S6 -> Y | J38: =T6 -> 3L | K38: =U6 -> 3.5 | L38: =V6 -> Loft | M38: =W6 -> 500
I39: =S7 -> Y | J39: =T7 -> 3L | K39: =U7 -> 3.5 | L39: =V7 -> Loft | M39: =W7 -> 500
I40: =S8 -> Y | J40: =T8 -> 3L | K40: =U8 -> 3.5 | L40: =V8 -> Loft | M40: =W8 -> 500
I41: =S9 -> Y | J41: =T9 -> 3L | K41: =U9 -> 3.5 | L41: =V9 -> Loft | M41: =W9 -> 500
I42: =S10 -> Y | J42: =T10 -> 3L | K42: =U10 -> 3.5 | L42: =V10 -> Loft | M42: =W10 -> 500
...

Sheet EICHER
A1: Order ID | B1: Date | C1: Sales | D1: New Party | E1: Route | F1: Party Code | G1: Party Name | H1: Area | I1: Remarks | J1: Tank | K1: Size | L1: Qty | M1: Col | N1: Lay | O1: Rate | P1: Tank | Q1: Size | R1: Qty | S1: Col | T1: Lay | U1: Rate | V1: Tank | W1: Size | X1: Qty | Y1: Col | Z1: Lay | AA1: Rate | AB1: Tank | AC1: Size | AD1: Qty | AE1: Col | AF1: Lay | AG1: Rate | AH1: Tank | AI1: Size | AJ1: Qty | AK1: Col | AL1: Lay | AM1: Rate | AN1: Tank | AO1: Size | AP1: Qty | AQ1: Col | AR1: Lay | AS1: Rate | AT1: Tank | AU1: Size | AV1: Qty | AW1: Col | AX1: Lay | AY1: Rate | AZ1: Tank | BA1: Size | BB1: Qty | BC1: Col | BD1: Lay | BE1: Rate | BF1: Tank | BG1: Size | BH1: Qty | BI1: Col | BJ1: Lay | BK1: Rate | BL1: Tank | BM1: Size | BN1: Qty | BO1: Col | BP1: Lay | BQ1: Rate | BR1: Terms | BS1: Site Delivery | BT1: Ltrs
A2: 21420 | B2: 46031 | C2: A/C | D2: No | E2: AP | F2: AP08 | G2: PAWAN PUTRA AGENCY | H2: TIRUPATHI | J2: AG | K2: 1500 | L2: 8 | M2: Y | N2: 3L | O2: 3.5 | P2: AG | Q2: 1000 | R2: 10 | S2: Y | T2: 3L | U2: 3.5 | V2: AG | W2: 750 | X2: 10 | Y2: Y | Z2: 3L | AA2: 3.5 | AB2: AG | AC2: 500 | AD2: 20 | AE2: Y | AF2: 3L | AG2: 3.5 | BR2: COD | BS2: 3L-0.50 | BT2: =K2*L2+Q2*R2+W2*X2+AC2*AD2+AI2*AJ2+AO2*AP2+AU2*AV2+BA2*BB2+BG2*BH2+BM2*BN2 -> 39500
H14: =J2 -> AG | I14: =K2 -> 1500 | J14: =L2 -> 8 | K14: =M2 -> Y | L14: =N2 -> 3L | O14: =J2 -> AG | P14: =N2 -> 3L | Q14: =O2 -> 3.5 | R14: =P2 -> AG | S14: =T2 -> 3L | T14: =U2 -> 3.5 | U14: =V2 -> AG | V14: =Z2 -> 3L | W14: =AA2 -> 3.5 | X14: =AB2 -> AG | Y14: =AF2 -> 3L | Z14: =AG2 -> 3.5 | AA14: =AH2 -> 0 | AB14: =AL2 -> 0 | AC14: =AM2 -> 0 | AD14: =AN2 -> 0 | AE14: =AR2 -> 0 | AF14: =AS2 -> 0 | AG14: =AT2 -> 0 | AH14: =AX2 -> 0 | AI14: =AY2 -> 0 | AJ14: =AZ2 -> 0 | AK14: =BD2 -> 0 | AL14: =BE2 -> 0 | AM14: =BF2 -> 0 | AN14: =BJ2 -> 0 | AO14: =BK2 -> 0 | AP14: =BL2 -> 0 | AQ14: =BP2 -> 0 | AR14: =BQ2 -> 0 | AT14: 1 | AU14: =IF($P$14="3L",$Q$14,IF($S$14="3L",$T$14,IF($V$14="3L",$W$14,IF($Y$14="3L",$Z$14,IF($AB$14="3L",$AC$14,IF($AE$14="3L",$AF$14,IF($AH$14="3L",$AI$14,IF($AK$14="3L",$AL$14,IF($AN$14="3L",$AO$14,IF($AQ$14="3L",$AR$14,"")))))))))) -> 3.5 | AV14: =IF($P$14="4L",$Q$14,IF($S$14="4L",$T$14,IF($V$14="4L",$W$14,IF($Y$14="4L",$Z$14,IF($AB$14="4L",$AC$14,IF($AE$14="4L",$AF$14,IF($AH$14="4L",$AI$14,IF($AK$14="4L",$AL$14,IF($AN$14="4L",$AO$14,IF($AQ$14="4L",$AR$14,"")))))))))) | AW14: =IF($P$14="5L",$Q$14,IF($S$14="5L",$T$14,IF($V$14="5L",$W$14,IF($Y$14="5L",$Z$14,IF($AB$14="5L",$AC$14,IF($AE$14="5L",$AF$14,IF($AH$14="5L",$AI$14,IF($AK$14="5L",$AL$14,IF($AN$14="5L",$AO$14,IF($AQ$14="5L",$AR$14,"")))))))))) | AX14: =IF($P$14="6L",$Q$14,IF($S$14="6L",$T$14,IF($V$14="6L",$W$14,IF($Y$14="6L",$Z$14,IF($AB$14="6L",$AC$14,IF($AE$14="6L",$AF$14,IF($AH$14="6L",$AI$14,IF($AK$14="6L",$AL$14,IF($AN$14="6L",$AO$14,IF($AQ$14="6L",$AR$14,"")))))))))) | AY14: =IF($P$14="7L",$Q$14,IF($S$14="7L",$T$14,IF($V$14="7L",$W$14,IF($Y$14="7L",$Z$14,IF($AB$14="7L",$AC$14,IF($AE$14="7L",$AF$14,IF($AH$14="7L",$AI$14,IF($AK$14="7L",$AL$14,IF($AN$14="7L",$AO$14,IF($AQ$14="7L",$AR$14,"")))))))))) | AZ14: =IF($O$14="LOFT",$Q$14,IF($R$14="LOFT",$T$14,IF($U$14="LOFT",$W$14,IF($X$14="LOFT",$Z$14,IF($AA$14="LOFT",$AC$14,IF($AD$14="LOFT",$AF$14,IF($AG$14="LOFT",$AI$14,IF($AJ$14="LOFT",$AL$14,IF($AM$14="LOFT",$AO$14,IF($AP$14="LOFT",$AR$14,"")))))))))) | BA14: =IF($O$14="UT",$Q$14,IF($R$14="UT",$T$14,IF($U$14="UT",$W$14,IF($X$14="UT",$Z$14,IF($AA$14="UT",$AC$14,IF($AD$14="UT",$AF$14,IF($AG$14="UT",$AI$14,IF($AJ$14="UT",$AL$14,IF($AM$14="UT",$AO$14,IF($AP$14="UT",$AR$14,"")))))))))) | BB14: =IF($O$14="HT",$Q$14,IF($R$14="HT",$T$14,IF($U$14="HT",$W$14,IF($X$14="HT",$Z$14,IF($AA$14="HT",$AC$14,IF($AD$14="HT",$AF$14,IF($AG$14="HT",$AI$14,IF($AJ$14="HT",$AL$14,IF($AM$14="HT",$AO$14,IF($AP$14="HT",$AR$14,"")))))))))) | BC14: =IF($O$14="PURE",$Q$14,IF($R$14="PURE",$T$14,IF($U$14="PURE",$W$14,IF($X$14="PURE",$Z$14,IF($AA$14="PURE",$AC$14,IF($AD$14="PURE",$AF$14,IF($AG$14="PURE",$AI$14,IF($AJ$14="PURE",$AL$14,IF($AM$14="PURE",$AO$14,IF($AP$14="PURE",$AR$14,"")))))))))) | BD14: =IF($P$14="FUM",$Q$14,IF($S$14="FUM",$T$14,IF($V$14="FUM",$W$14,IF($Y$14="FUM",$Z$14,IF($AB$14="FUM",$AC$14,IF($AE$14="FUM",$AF$14,IF($AH$14="FUM",$AI$14,IF($AK$14="FUM",$AL$14,IF($AN$14="FUM",$AO$14,IF($AQ$14="FUM",$AR$14,""))))))))))
H15: =J3 -> 0 | I15: =K3 -> 0 | J15: =L3 -> 0 | K15: =M3 -> 0 | L15: =N3 -> 0 | O15: =J3 -> 0 | P15: =N3 -> 0 | Q15: =O3 -> 0 | R15: =P3 -> 0 | S15: =T3 -> 0 | T15: =U3 -> 0 | U15: =V3 -> 0 | V15: =Z3 -> 0 | W15: =AA3 -> 0 | X15: =AB3 -> 0 | Y15: =AF3 -> 0 | Z15: =AG3 -> 0 | AA15: =AH3 -> 0 | AB15: =AL3 -> 0 | AC15: =AM3 -> 0 | AD15: =AN3 -> 0 | AE15: =AR3 -> 0 | AF15: =AS3 -> 0 | AG15: =AT3 -> 0 | AH15: =AX3 -> 0 | AI15: =AY3 -> 0 | AJ15: =AZ3 -> 0 | AK15: =BD3 -> 0 | AL15: =BE3 -> 0 | AM15: =BF3 -> 0 | AN15: =BJ3 -> 0 | AO15: =BK3 -> 0 | AP15: =BL3 -> 0 | AQ15: =BP3 -> 0 | AR15: =BQ3 -> 0 | AT15: 2 | AU15: =IF($P$15="3L",$Q$15,IF($S$15="3L",$T$15,IF($V$15="3L",$W$15,IF($Y$15="3L",$Z$15,IF($AB$15="3L",$AC$15,IF($AE$15="3L",$AF$15,IF($AH$15="3L",$AI$15,IF($AK$15="3L",$AL$15,IF($AN$15="3L",$AO$15,IF($AQ$15="3L",$AR$15,"")))))))))) | AV15: =IF($P$15="4L",$Q$15,IF($S$15="4L",$T$15,IF($V$15="4L",$W$15,IF($Y$15="4L",$Z$15,IF($AB$15="4L",$AC$15,IF($AE$15="4L",$AF$15,IF($AH$15="4L",$AI$15,IF($AK$15="4L",$AL$15,IF($AN$15="4L",$AO$15,IF($AQ$15="4L",$AR$15,"")))))))))) | AW15: =IF($P$15="5L",$Q$15,IF($S$15="5L",$T$15,IF($V$15="5L",$W$15,IF($Y$15="5L",$Z$15,IF($AB$15="5L",$AC$15,IF($AE$15="5L",$AF$15,IF($AH$15="5L",$AI$15,IF($AK$15="5L",$AL$15,IF($AN$15="5L",$AO$15,IF($AQ$15="5L",$AR$15,"")))))))))) | AX15: =IF($P$15="6L",$Q$15,IF($S$15="6L",$T$15,IF($V$15="6L",$W$15,IF($Y$15="6L",$Z$15,IF($AB$15="6L",$AC$15,IF($AE$15="6L",$AF$15,IF($AH$15="6L",$AI$15,IF($AK$15="6L",$AL$15,IF($AN$15="6L",$AO$15,IF($AQ$15="6L",$AR$15,"")))))))))) | AY15: =IF($P$15="7L",$Q$15,IF($S$15="7L",$T$15,IF($V$15="7L",$W$15,IF($Y$15="7L",$Z$15,IF($AB$15="7L",$AC$15,IF($AE$15="7L",$AF$15,IF($AH$15="7L",$AI$15,IF($AK$15="7L",$AL$15,IF($AN$15="7L",$AO$15,IF($AQ$15="7L",$AR$15,"")))))))))) | AZ15: =IF($O$14="LOFT",$Q$14,IF($R$14="LOFT",$T$14,IF($U$14="LOFT",$W$14,IF($X$14="LOFT",$Z$14,IF($AA$14="LOFT",$AC$14,IF($AD$14="LOFT",$AF$14,IF($AG$14="LOFT",$AI$14,IF($AJ$14="LOFT",$AL$14,IF($AM$14="LOFT",$AO$14,IF($AP$14="LOFT",$AR$14,"")))))))))) | BA15: =IF($O$14="UT",$Q$14,IF($R$14="UT",$T$14,IF($U$14="UT",$W$14,IF($X$14="UT",$Z$14,IF($AA$14="UT",$AC$14,IF($AD$14="UT",$AF$14,IF($AG$14="UT",$AI$14,IF($AJ$14="UT",$AL$14,IF($AM$14="UT",$AO$14,IF($AP$14="UT",$AR$14,"")))))))))) | BB15: =IF($O$14="HT",$Q$14,IF($R$14="HT",$T$14,IF($U$14="HT",$W$14,IF($X$14="HT",$Z$14,IF($AA$14="HT",$AC$14,IF($AD$14="HT",$AF$14,IF($AG$14="HT",$AI$14,IF($AJ$14="HT",$AL$14,IF($AM$14="HT",$AO$14,IF($AP$14="HT",$AR$14,"")))))))))) | BC15: =IF($O$14="PURE",$Q$14,IF($R$14="PURE",$T$14,IF($U$14="PURE",$W$14,IF($X$14="PURE",$Z$14,IF($AA$14="PURE",$AC$14,IF($AD$14="PURE",$AF$14,IF($AG$14="PURE",$AI$14,IF($AJ$14="PURE",$AL$14,IF($AM$14="PURE",$AO$14,IF($AP$14="PURE",$AR$14,"")))))))))) | BD15: =IF($P$15="FUM",$Q$15,IF($S$15="FUM",$T$15,IF($V$15="FUM",$W$15,IF($Y$15="FUM",$Z$15,IF($AB$15="FUM",$AC$15,IF($AE$15="FUM",$AF$15,IF($AH$15="FUM",$AI$15,IF($AK$15="FUM",$AL$15,IF($AN$15="FUM",$AO$15,IF($AQ$15="FUM",$AR$15,""))))))))))
H16: =J4 -> 0 | I16: =K4 -> 0 | J16: =L4 -> 0 | K16: =M4 -> 0 | L16: =N4 -> 0 | O16: =J4 -> 0 | P16: =N4 -> 0 | Q16: =O4 -> 0 | R16: =P4 -> 0 | S16: =T4 -> 0 | T16: =U4 -> 0 | U16: =V4 -> 0 | V16: =Z4 -> 0 | W16: =AA4 -> 0 | X16: =AB4 -> 0 | Y16: =AF4 -> 0 | Z16: =AG4 -> 0 | AA16: =AH4 -> 0 | AB16: =AL4 -> 0 | AC16: =AM4 -> 0 | AD16: =AN4 -> 0 | AE16: =AR4 -> 0 | AF16: =AS4 -> 0 | AG16: =AT4 -> 0 | AH16: =AX4 -> 0 | AI16: =AY4 -> 0 | AJ16: =AZ4 -> 0 | AK16: =BD4 -> 0 | AL16: =BE4 -> 0 | AM16: =BF4 -> 0 | AN16: =BJ4 -> 0 | AO16: =BK4 -> 0 | AP16: =BL4 -> 0 | AQ16: =BP4 -> 0 | AR16: =BQ4 -> 0 | AT16: 3 | AU16: =IF($P$16="3L",$Q$16,IF($S$16="3L",$T$16,IF($V$16="3L",$W$16,IF($Y$16="3L",$Z$16,IF($AB$16="3L",$AC$16,IF($AE$16="3L",$AF$16,IF($AH$16="3L",$AI$16,IF($AK$16="3L",$AL$16,IF($AN$16="3L",$AO$16,IF($AQ$16="3L",$AR$16,"")))))))))) | AV16: =IF($P$16="4L",$Q$16,IF($S$16="4L",$T$16,IF($V$16="4L",$W$16,IF($Y$16="4L",$Z$16,IF($AB$16="4L",$AC$16,IF($AE$16="4L",$AF$16,IF($AH$16="4L",$AI$16,IF($AK$16="4L",$AL$16,IF($AN$16="4L",$AO$16,IF($AQ$16="4L",$AR$16,"")))))))))) | AW16: =IF($P$16="5L",$Q$16,IF($S$16="5L",$T$16,IF($V$16="5L",$W$16,IF($Y$16="5L",$Z$16,IF($AB$16="5L",$AC$16,IF($AE$16="5L",$AF$16,IF($AH$16="5L",$AI$16,IF($AK$16="5L",$AL$16,IF($AN$16="5L",$AO$16,IF($AQ$16="5L",$AR$16,"")))))))))) | AX16: =IF($P$16="6L",$Q$16,IF($S$16="6L",$T$16,IF($V$16="6L",$W$16,IF($Y$16="6L",$Z$16,IF($AB$16="6L",$AC$16,IF($AE$16="6L",$AF$16,IF($AH$16="6L",$AI$16,IF($AK$16="6L",$AL$16,IF($AN$16="6L",$AO$16,IF($AQ$16="6L",$AR$16,"")))))))))) | AY16: =IF($P$16="7L",$Q$16,IF($S$16="7L",$T$16,IF($V$16="7L",$W$16,IF($Y$16="7L",$Z$16,IF($AB$16="7L",$AC$16,IF($AE$16="7L",$AF$16,IF($AH$16="7L",$AI$16,IF($AK$16="7L",$AL$16,IF($AN$16="7L",$AO$16,IF($AQ$16="7L",$AR$16,"")))))))))) | AZ16: =IF($O$14="LOFT",$Q$14,IF($R$14="LOFT",$T$14,IF($U$14="LOFT",$W$14,IF($X$14="LOFT",$Z$14,IF($AA$14="LOFT",$AC$14,IF($AD$14="LOFT",$AF$14,IF($AG$14="LOFT",$AI$14,IF($AJ$14="LOFT",$AL$14,IF($AM$14="LOFT",$AO$14,IF($AP$14="LOFT",$AR$14,"")))))))))) | BA16: =IF($O$14="UT",$Q$14,IF($R$14="UT",$T$14,IF($U$14="UT",$W$14,IF($X$14="UT",$Z$14,IF($AA$14="UT",$AC$14,IF($AD$14="UT",$AF$14,IF($AG$14="UT",$AI$14,IF($AJ$14="UT",$AL$14,IF($AM$14="UT",$AO$14,IF($AP$14="UT",$AR$14,"")))))))))) | BB16: =IF($O$14="HT",$Q$14,IF($R$14="HT",$T$14,IF($U$14="HT",$W$14,IF($X$14="HT",$Z$14,IF($AA$14="HT",$AC$14,IF($AD$14="HT",$AF$14,IF($AG$14="HT",$AI$14,IF($AJ$14="HT",$AL$14,IF($AM$14="HT",$AO$14,IF($AP$14="HT",$AR$14,"")))))))))) | BC16: =IF($O$14="PURE",$Q$14,IF($R$14="PURE",$T$14,IF($U$14="PURE",$W$14,IF($X$14="PURE",$Z$14,IF($AA$14="PURE",$AC$14,IF($AD$14="PURE",$AF$14,IF($AG$14="PURE",$AI$14,IF($AJ$14="PURE",$AL$14,IF($AM$14="PURE",$AO$14,IF($AP$14="PURE",$AR$14,"")))))))))) | BD16: =IF($P$16="FUM",$Q$16,IF($S$16="FUM",$T$16,IF($V$16="FUM",$W$16,IF($Y$16="FUM",$Z$16,IF($AB$16="FUM",$AC$16,IF($AE$16="FUM",$AF$16,IF($AH$16="FUM",$AI$16,IF($AK$16="FUM",$AL$16,IF($AN$16="FUM",$AO$16,IF($AQ$16="FUM",$AR$16,""))))))))))
